Workbook

Sheet WBS_진행관리
A1: WBS ID | B1: 번호 | C1: 분담 범위 | D1: 담당자 | E1: 작업 | F1: 완료 기준 | G1: 시작일 | H1: 종료일 | I1: 계획(%) | J1: 실적(%) | K1: 진행률(%) | L1: 완료여부 | M1: 진행상태 | N1: 비고 | O1: 6월 2주 | P1: 6월 3주 | Q1: 6월 4주 | R1: 6월 5주 | S1: 7월 1주 | T1: 7월 2주 | U1: 7월 3주 | V1: 7월 4주 | W1: 7월 5주
A2: WBS-001 | B2: 공통 | C2: 공통 기반 / 구현 기준 | D2: 이현겸 | E2: 공통 response, error, validation, idempotency, config 기준 확인 | F2: 각 담당자가 같은 공통 기준으로 Controller/Service/Mapper 구현 | G2: 46195 | H2: 46206 | I2: 1 | J2: 1 | K2: =IF(LEN($J2&"")=0,"",$J2) -> 1 | L2: =IF(LEN($K2&"")=0,"",IF($K2>=1,"완료",IF($K2>0,"진행","준비"))) -> 완료 | M2: =IF(OR(LEN($I2&"")=0,LEN($J2&"")=0),"",IF($J2>=1,"정상",IF($J2>=$I2,"정상",IF($I2-$J2>0.1,"지연","주의")))) -> 정상 | N2: 공통 | O2: =IF(OR($G2>'설정'!$D$4,$H2<'설정'!$C$4),"",IF($L2="완료","완료",IF($M2="지연","지연",IF($M2="주의","주의",IF($J2>0,"진행","계획"))))) | P2: =IF(OR($G2>'설정'!$D$5,$H2<'설정'!$C$5),"",IF($L2="완료","완료",IF($M2="지연","지연",IF($M2="주의","주의",IF($J2>0,"진행","계획"))))) | Q2: =IF(OR($G2>'설정'!$D$6,$H2<'설정'!$C$6),"",IF($L2="완료","완료",IF($M2="지연","지연",IF($M2="주의","주의",IF($J2>0,"진행","계획"))))) -> 완료 | R2: =IF(OR($G2>'설정'!$D$7,$H2<'설정'!$C$7),"",IF($L2="완료","완료",IF($M2="지연","지연",IF($M2="주의","주의",IF($J2>0,"진행","계획"))))) -> 완료 | S2: =IF(OR($G2>'설정'!$D$8,$H2<'설정'!$C$8),"",IF($L2="완료","완료",IF($M2="지연","지연",IF($M2="주의","주의",IF($J2>0,"진행","계획"))))) -> 완료 | T2: =IF(OR($G2>'설정'!$D$9,$H2<'설정'!$C$9),"",IF($L2="완료","완료",IF($M2="지연","지연",IF($M2="주의","주의",IF($J2>0,"진행","계획"))))) | U2: =IF(OR($G2>'설정'!$D$10,$H2<'설정'!$C$10),"",IF($L2="완료","완료",IF($M2="지연","지연",IF($M2="주의","주의",IF($J2>0,"진행","계획"))))) | V2: =IF(OR($G2>'설정'!$D$11,$H2<'설정'!$C$11),"",IF($L2="완료","완료",IF($M2="지연","지연",IF($M2="주의","주의",IF($J2>0,"진행","계획"))))) | W2: =IF(OR($G2>'설정'!$D$12,$H2<'설정'!$C$12),"",IF($L2="완료","완료",IF($M2="지연","지연",IF($M2="주의","주의",IF($J2>0,"진행","계획")))))
A3: WBS-002 | C3: 문서 총괄 | E3: 최종 Word 기획서, Notion 기획서, SRS, 매핑표 정책 문구 정합성 확인 | F3: 공통 로그인, ChatGPT API, 테스트케이스 실행 채점 기준 일치 | G3: 46184 | H3: 46230 | I3: 1 | J3: 1 | K3: =IF(LEN($J3&"")=0,"",$J3) -> 1 | L3: =IF(LEN($K3&"")=0,"",IF($K3>=1,"완료",IF($K3>0,"진행","준비"))) -> 완료 | M3: =IF(OR(LEN($I3&"")=0,LEN($J3&"")=0),"",IF($J3>=1,"정상",IF($J3>=$I3,"정상",IF($I3-$J3>0.1,"지연","주의")))) -> 정상 | N3: 공통 | O3: =IF(OR($G3>'설정'!$D$4,$H3<'설정'!$C$4),"",IF($L3="완료","완료",IF($M3="지연","지연",IF($M3="주의","주의",IF($J3>0,"진행","계획"))))) -> 완료 | P3: =IF(OR($G3>'설정'!$D$5,$H3<'설정'!$C$5),"",IF($L3="완료","완료",IF($M3="지연","지연",IF($M3="주의","주의",IF($J3>0,"진행","계획"))))) -> 완료 | Q3: =IF(OR($G3>'설정'!$D$6,$H3<'설정'!$C$6),"",IF($L3="완료","완료",IF($M3="지연","지연",IF($M3="주의","주의",IF($J3>0,"진행","계획"))))) -> 완료 | R3: =IF(OR($G3>'설정'!$D$7,$H3<'설정'!$C$7),"",IF($L3="완료","완료",IF($M3="지연","지연",IF($M3="주의","주의",IF($J3>0,"진행","계획"))))) -> 완료 | S3: =IF(OR($G3>'설정'!$D$8,$H3<'설정'!$C$8),"",IF($L3="완료","완료",IF($M3="지연","지연",IF($M3="주의","주의",IF($J3>0,"진행","계획"))))) -> 완료 | T3: =IF(OR($G3>'설정'!$D$9,$H3<'설정'!$C$9),"",IF($L3="완료","완료",IF($M3="지연","지연",IF($M3="주의","주의",IF($J3>0,"진행","계획"))))) -> 완료 | U3: =IF(OR($G3>'설정'!$D$10,$H3<'설정'!$C$10),"",IF($L3="완료","완료",IF($M3="지연","지연",IF($M3="주의","주의",IF($J3>0,"진행","계획"))))) -> 완료 | V3: =IF(OR($G3>'설정'!$D$11,$H3<'설정'!$C$11),"",IF($L3="완료","완료",IF($M3="지연","지연",IF($M3="주의","주의",IF($J3>0,"진행","계획"))))) -> 완료 | W3: =IF(OR($G3>'설정'!$D$12,$H3<'설정'!$C$12),"",IF($L3="완료","완료",IF($M3="지연","지연",IF($M3="주의","주의",IF($J3>0,"진행","계획"))))) -> 완료
A4: WBS-003 | C4: 제출 파일 관리 | E4: docs/최종 문서 파일 구성과 commit 포함 여부 정리 | F4: 제출 파일 목록과 repo 반영 여부 팀 공유 | G4: 46184 | H4: 46230 | I4: 1 | J4: 1 | K4: =IF(LEN($J4&"")=0,"",$J4) -> 1 | L4: =IF(LEN($K4&"")=0,"",IF($K4>=1,"완료",IF($K4>0,"진행","준비"))) -> 완료 | M4: =IF(OR(LEN($I4&"")=0,LEN($J4&"")=0),"",IF($J4>=1,"정상",IF($J4>=$I4,"정상",IF($I4-$J4>0.1,"지연","주의")))) -> 정상 | N4: 공통 | O4: =IF(OR($G4>'설정'!$D$4,$H4<'설정'!$C$4),"",IF($L4="완료","완료",IF($M4="지연","지연",IF($M4="주의","주의",IF($J4>0,"진행","계획"))))) -> 완료 | P4: =IF(OR($G4>'설정'!$D$5,$H4<'설정'!$C$5),"",IF($L4="완료","완료",IF($M4="지연","지연",IF($M4="주의","주의",IF($J4>0,"진행","계획"))))) -> 완료 | Q4: =IF(OR($G4>'설정'!$D$6,$H4<'설정'!$C$6),"",IF($L4="완료","완료",IF($M4="지연","지연",IF($M4="주의","주의",IF($J4>0,"진행","계획"))))) -> 완료 | R4: =IF(OR($G4>'설정'!$D$7,$H4<'설정'!$C$7),"",IF($L4="완료","완료",IF($M4="지연","지연",IF($M4="주의","주의",IF($J4>0,"진행","계획"))))) -> 완료 | S4: =IF(OR($G4>'설정'!$D$8,$H4<'설정'!$C$8),"",IF($L4="완료","완료",IF($M4="지연","지연",IF($M4="주의","주의",IF($J4>0,"진행","계획"))))) -> 완료 | T4: =IF(OR($G4>'설정'!$D$9,$H4<'설정'!$C$9),"",IF($L4="완료","완료",IF($M4="지연","지연",IF($M4="주의","주의",IF($J4>0,"진행","계획"))))) -> 완료 | U4: =IF(OR($G4>'설정'!$D$10,$H4<'설정'!$C$10),"",IF($L4="완료","완료",IF($M4="지연","지연",IF($M4="주의","주의",IF($J4>0,"진행","계획"))))) -> 완료 | V4: =IF(OR($G4>'설정'!$D$11,$H4<'설정'!$C$11),"",IF($L4="완료","완료",IF($M4="지연","지연",IF($M4="주의","주의",IF($J4>0,"진행","계획"))))) -> 완료 | W4: =IF(OR($G4>'설정'!$D$12,$H4<'설정'!$C$12),"",IF($L4="완료","완료",IF($M4="지연","지연",IF($M4="주의","주의",IF($J4>0,"진행","계획"))))) -> 완료
A5: WBS-004 | B5: 1번 | C5: Auth / Security | D5: 이정하 | E5: 회원가입, 공통 로그인, 로그아웃, session 저장/조회 흐름 구현 | F5: 로그인/로그아웃과 session user 사용 가능 | G5: 46204 | H5: 46214 | I5: 1 | J5: 1 | K5: =IF(LEN($J5&"")=0,"",$J5) -> 1 | L5: =IF(LEN($K5&"")=0,"",IF($K5>=1,"완료",IF($K5>0,"진행","준비"))) -> 완료 | M5: =IF(OR(LEN($I5&"")=0,LEN($J5&"")=0),"",IF($J5>=1,"정상",IF($J5>=$I5,"정상",IF($I5-$J5>0.1,"지연","주의")))) -> 정상 | N5: 인증 | O5: =IF(OR($G5>'설정'!$D$4,$H5<'설정'!$C$4),"",IF($L5="완료","완료",IF($M5="지연","지연",IF($M5="주의","주의",IF($J5>0,"진행","계획"))))) | P5: =IF(OR($G5>'설정'!$D$5,$H5<'설정'!$C$5),"",IF($L5="완료","완료",IF($M5="지연","지연",IF($M5="주의","주의",IF($J5>0,"진행","계획"))))) | Q5: =IF(OR($G5>'설정'!$D$6,$H5<'설정'!$C$6),"",IF($L5="완료","완료",IF($M5="지연","지연",IF($M5="주의","주의",IF($J5>0,"진행","계획"))))) | R5: =IF(OR($G5>'설정'!$D$7,$H5<'설정'!$C$7),"",IF($L5="완료","완료",IF($M5="지연","지연",IF($M5="주의","주의",IF($J5>0,"진행","계획"))))) | S5: =IF(OR($G5>'설정'!$D$8,$H5<'설정'!$C$8),"",IF($L5="완료","완료",IF($M5="지연","지연",IF($M5="주의","주의",IF($J5>0,"진행","계획"))))) -> 완료 | T5: =IF(OR($G5>'설정'!$D$9,$H5<'설정'!$C$9),"",IF($L5="완료","완료",IF($M5="지연","지연",IF($M5="주의","주의",IF($J5>0,"진행","계획"))))) -> 완료 | U5: =IF(OR($G5>'설정'!$D$10,$H5<'설정'!$C$10),"",IF($L5="완료","완료",IF($M5="지연","지연",IF($M5="주의","주의",IF($J5>0,"진행","계획"))))) | V5: =IF(OR($G5>'설정'!$D$11,$H5<'설정'!$C$11),"",IF($L5="완료","완료",IF($M5="지연","지연",IF($M5="주의","주의",IF($J5>0,"진행","계획"))))) | W5: =IF(OR($G5>'설정'!$D$12,$H5<'설정'!$C$12),"",IF($L5="완료","완료",IF($M5="지연","지연",IF($M5="주의","주의",IF($J5>0,"진행","계획")))))
A6: WBS-005 | C6: Role redirect | E6: ROLE_USER는 /learning, ROLE_ADMIN은 /admin 이동 구현 | F6: 관리자 별도 로그인 없이 공통 로그인에서 role별 이동 | G6: 46204 | H6: 46214 | I6: 1 | J6: 1 | K6: =IF(LEN($J6&"")=0,"",$J6) -> 1 | L6: =IF(LEN($K6&"")=0,"",IF($K6>=1,"완료",IF($K6>0,"진행","준비"))) -> 완료 | M6: =IF(OR(LEN($I6&"")=0,LEN($J6&"")=0),"",IF($J6>=1,"정상",IF($J6>=$I6,"정상",IF($I6-$J6>0.1,"지연","주의")))) -> 정상 | N6: 인증 | O6: =IF(OR($G6>'설정'!$D$4,$H6<'설정'!$C$4),"",IF($L6="완료","완료",IF($M6="지연","지연",IF($M6="주의","주의",IF($J6>0,"진행","계획"))))) | P6: =IF(OR($G6>'설정'!$D$5,$H6<'설정'!$C$5),"",IF($L6="완료","완료",IF($M6="지연","지연",IF($M6="주의","주의",IF($J6>0,"진행","계획"))))) | Q6: =IF(OR($G6>'설정'!$D$6,$H6<'설정'!$C$6),"",IF($L6="완료","완료",IF($M6="지연","지연",IF($M6="주의","주의",IF($J6>0,"진행","계획"))))) | R6: =IF(OR($G6>'설정'!$D$7,$H6<'설정'!$C$7),"",IF($L6="완료","완료",IF($M6="지연","지연",IF($M6="주의","주의",IF($J6>0,"진행","계획"))))) | S6: =IF(OR($G6>'설정'!$D$8,$H6<'설정'!$C$8),"",IF($L6="완료","완료",IF($M6="지연","지연",IF($M6="주의","주의",IF($J6>0,"진행","계획"))))) -> 완료 | T6: =IF(OR($G6>'설정'!$D$9,$H6<'설정'!$C$9),"",IF($L6="완료","완료",IF($M6="지연","지연",IF($M6="주의","주의",IF($J6>0,"진행","계획"))))) -> 완료 | U6: =IF(OR($G6>'설정'!$D$10,$H6<'설정'!$C$10),"",IF($L6="완료","완료",IF($M6="지연","지연",IF($M6="주의","주의",IF($J6>0,"진행","계획"))))) | V6: =IF(OR($G6>'설정'!$D$11,$H6<'설정'!$C$11),"",IF($L6="완료","완료",IF($M6="지연","지연",IF($M6="주의","주의",IF($J6>0,"진행","계획"))))) | W6: =IF(OR($G6>'설정'!$D$12,$H6<'설정'!$C$12),"",IF($L6="완료","완료",IF($M6="지연","지연",IF($M6="주의","주의",IF($J6>0,"진행","계획")))))
A7: WBS-006 | C7: Auth guard | E7: LoginRequiredInterceptor, AdminRequiredInterceptor, owner guard 연결 | F7: 비로그인/일반 사용자/관리자 접근 경계 동작 | G7: 46202 | H7: 46214 | I7: 1 | J7: 1 | K7: =IF(LEN($J7&"")=0,"",$J7) -> 1 | L7: =IF(LEN($K7&"")=0,"",IF($K7>=1,"완료",IF($K7>0,"진행","준비"))) -> 완료 | M7: =IF(OR(LEN($I7&"")=0,LEN($J7&"")=0),"",IF($J7>=1,"정상",IF($J7>=$I7,"정상",IF($I7-$J7>0.1,"지연","주의")))) -> 정상 | N7: 인증 | O7: =IF(OR($G7>'설정'!$D$4,$H7<'설정'!$C$4),"",IF($L7="완료","완료",IF($M7="지연","지연",IF($M7="주의","주의",IF($J7>0,"진행","계획"))))) | P7: =IF(OR($G7>'설정'!$D$5,$H7<'설정'!$C$5),"",IF($L7="완료","완료",IF($M7="지연","지연",IF($M7="주의","주의",IF($J7>0,"진행","계획"))))) | Q7: =IF(OR($G7>'설정'!$D$6,$H7<'설정'!$C$6),"",IF($L7="완료","완료",IF($M7="지연","지연",IF($M7="주의","주의",IF($J7>0,"진행","계획"))))) | R7: =IF(OR($G7>'설정'!$D$7,$H7<'설정'!$C$7),"",IF($L7="완료","완료",IF($M7="지연","지연",IF($M7="주의","주의",IF($J7>0,"진행","계획"))))) -> 완료 | S7: =IF(OR($G7>'설정'!$D$8,$H7<'설정'!$C$8),"",IF($L7="완료","완료",IF($M7="지연","지연",IF($M7="주의","주의",IF($J7>0,"진행","계획"))))) -> 완료 | T7: =IF(OR($G7>'설정'!$D$9,$H7<'설정'!$C$9),"",IF($L7="완료","완료",IF($M7="지연","지연",IF($M7="주의","주의",IF($J7>0,"진행","계획"))))) -> 완료 | U7: =IF(OR($G7>'설정'!$D$10,$H7<'설정'!$C$10),"",IF($L7="완료","완료",IF($M7="지연","지연",IF($M7="주의","주의",IF($J7>0,"진행","계획"))))) | V7: =IF(OR($G7>'설정'!$D$11,$H7<'설정'!$C$11),"",IF($L7="완료","완료",IF($M7="지연","지연",IF($M7="주의","주의",IF($J7>0,"진행","계획"))))) | W7: =IF(OR($G7>'설정'!$D$12,$H7<'설정'!$C$12),"",IF($L7="완료","완료",IF($M7="지연","지연",IF($M7="주의","주의",IF($J7>0,"진행","계획")))))
A8: WBS-007 | B8: 2번 | C8: 학습 / 커리큘럼 | D8: 조아진 | E8: 학습 메인, roadmap, lesson, progress, bookmark 조회/저장 구현 | F8: SR-003 학습 화면에 학습 상태와 진행률 표시 | G8: 46200 | H8: 46213 | I8: 1 | J8: 1 | K8: =IF(LEN($J8&"")=0,"",$J8) -> 1 | L8: =IF(LEN($K8&"")=0,"",IF($K8>=1,"완료",IF($K8>0,"진행","준비"))) -> 완료 | M8: =IF(OR(LEN($I8&"")=0,LEN($J8&"")=0),"",IF($J8>=1,"정상",IF($J8>=$I8,"정상",IF($I8-$J8>0.1,"지연","주의")))) -> 정상 | N8: 학습 | O8: =IF(OR($G8>'설정'!$D$4,$H8<'설정'!$C$4),"",IF($L8="완료","완료",IF($M8="지연","지연",IF($M8="주의","주의",IF($J8>0,"진행","계획"))))) | P8: =IF(OR($G8>'설정'!$D$5,$H8<'설정'!$C$5),"",IF($L8="완료","완료",IF($M8="지연","지연",IF($M8="주의","주의",IF($J8>0,"진행","계획"))))) | Q8: =IF(OR($G8>'설정'!$D$6,$H8<'설정'!$C$6),"",IF($L8="완료","완료",IF($M8="지연","지연",IF($M8="주의","주의",IF($J8>0,"진행","계획"))))) -> 완료 | R8: =IF(OR($G8>'설정'!$D$7,$H8<'설정'!$C$7),"",IF($L8="완료","완료",IF($M8="지연","지연",IF($M8="주의","주의",IF($J8>0,"진행","계획"))))) -> 완료 | S8: =IF(OR($G8>'설정'!$D$8,$H8<'설정'!$C$8),"",IF($L8="완료","완료",IF($M8="지연","지연",IF($M8="주의","주의",IF($J8>0,"진행","계획"))))) -> 완료 | T8: =IF(OR($G8>'설정'!$D$9,$H8<'설정'!$C$9),"",IF($L8="완료","완료",IF($M8="지연","지연",IF($M8="주의","주의",IF($J8>0,"진행","계획"))))) -> 완료 | U8: =IF(OR($G8>'설정'!$D$10,$H8<'설정'!$C$10),"",IF($L8="완료","완료",IF($M8="지연","지연",IF($M8="주의","주의",IF($J8>0,"진행","계획"))))) | V8: =IF(OR($G8>'설정'!$D$11,$H8<'설정'!$C$11),"",IF($L8="완료","완료",IF($M8="지연","지연",IF($M8="주의","주의",IF($J8>0,"진행","계획"))))) | W8: =IF(OR($G8>'설정'!$D$12,$H8<'설정'!$C$12),"",IF($L8="완료","완료",IF($M8="지연","지연",IF($M8="주의","주의",IF($J8>0,"진행","계획")))))
A9: WBS-008 | C9: 레벨 테스트 | E9: 8문항 제출, 정답 계산, Bronze/Silver/Gold 반영 흐름 구현 | F9: 0-2 Bronze, 3-5 Silver, 6-8 Gold 기준 DB 반영 | G9: 46203 | H9: 46213 | I9: 1 | J9: 1 | K9: =IF(LEN($J9&"")=0,"",$J9) -> 1 | L9: =IF(LEN($K9&"")=0,"",IF($K9>=1,"완료",IF($K9>0,"진행","준비"))) -> 완료 | M9: =IF(OR(LEN($I9&"")=0,LEN($J9&"")=0),"",IF($J9>=1,"정상",IF($J9>=$I9,"정상",IF($I9-$J9>0.1,"지연","주의")))) -> 정상 | N9: 학습 | O9: =IF(OR($G9>'설정'!$D$4,$H9<'설정'!$C$4),"",IF($L9="완료","완료",IF($M9="지연","지연",IF($M9="주의","주의",IF($J9>0,"진행","계획"))))) | P9: =IF(OR($G9>'설정'!$D$5,$H9<'설정'!$C$5),"",IF($L9="완료","완료",IF($M9="지연","지연",IF($M9="주의","주의",IF($J9>0,"진행","계획"))))) | Q9: =IF(OR($G9>'설정'!$D$6,$H9<'설정'!$C$6),"",IF($L9="완료","완료",IF($M9="지연","지연",IF($M9="주의","주의",IF($J9>0,"진행","계획"))))) | R9: =IF(OR($G9>'설정'!$D$7,$H9<'설정'!$C$7),"",IF($L9="완료","완료",IF($M9="지연","지연",IF($M9="주의","주의",IF($J9>0,"진행","계획"))))) -> 완료 | S9: =IF(OR($G9>'설정'!$D$8,$H9<'설정'!$C$8),"",IF($L9="완료","완료",IF($M9="지연","지연",IF($M9="주의","주의",IF($J9>0,"진행","계획"))))) -> 완료 | T9: =IF(OR($G9>'설정'!$D$9,$H9<'설정'!$C$9),"",IF($L9="완료","완료",IF($M9="지연","지연",IF($M9="주의","주의",IF($J9>0,"진행","계획"))))) -> 완료 | U9: =IF(OR($G9>'설정'!$D$10,$H9<'설정'!$C$10),"",IF($L9="완료","완료",IF($M9="지연","지연",IF($M9="주의","주의",IF($J9>0,"진행","계획"))))) | V9: =IF(OR($G9>'설정'!$D$11,$H9<'설정'!$C$11),"",IF($L9="완료","완료",IF($M9="지연","지연",IF($M9="주의","주의",IF($J9>0,"진행","계획"))))) | W9: =IF(OR($G9>'설정'!$D$12,$H9<'설정'!$C$12),"",IF($L9="완료","완료",IF($M9="지연","지연",IF($M9="주의","주의",IF($J9>0,"진행","계획")))))
A10: WBS-009 | C10: 출석 / unlock | E10: attendance/streak 기록과 level unlock owner contract 정리 | F10: unlock/attendance owner service 경유 | G10: 46204 | H10: 46215 | I10: 1 | J10: 1 | K10: =IF(LEN($J10&"")=0,"",$J10) -> 1 | L10: =IF(LEN($K10&"")=0,"",IF($K10>=1,"완료",IF($K10>0,"진행","준비"))) -> 완료 | M10: =IF(OR(LEN($I10&"")=0,LEN($J10&"")=0),"",IF($J10>=1,"정상",IF($J10>=$I10,"정상",IF($I10-$J10>0.1,"지연","주의")))) -> 정상 | N10: 학습 | O10: =IF(OR($G10>'설정'!$D$4,$H10<'설정'!$C$4),"",IF($L10="완료","완료",IF($M10="지연","지연",IF($M10="주의","주의",IF($J10>0,"진행","계획"))))) | P10: =IF(OR($G10>'설정'!$D$5,$H10<'설정'!$C$5),"",IF($L10="완료","완료",IF($M10="지연","지연",IF($M10="주의","주의",IF($J10>0,"진행","계획"))))) | Q10: =IF(OR($G10>'설정'!$D$6,$H10<'설정'!$C$6),"",IF($L10="완료","완료",IF($M10="지연","지연",IF($M10="주의","주의",IF($J10>0,"진행","계획"))))) | R10: =IF(OR($G10>'설정'!$D$7,$H10<'설정'!$C$7),"",IF($L10="완료","완료",IF($M10="지연","지연",IF($M10="주의","주의",IF($J10>0,"진행","계획"))))) | S10: =IF(OR($G10>'설정'!$D$8,$H10<'설정'!$C$8),"",IF($L10="완료","완료",IF($M10="지연","지연",IF($M10="주의","주의",IF($J10>0,"진행","계획"))))) -> 완료 | T10: =IF(OR($G10>'설정'!$D$9,$H10<'설정'!$C$9),"",IF($L10="완료","완료",IF($M10="지연","지연",IF($M10="주의","주의",IF($J10>0,"진행","계획"))))) -> 완료 | U10: =IF(OR($G10>'설정'!$D$10,$H10<'설정'!$C$10),"",IF($L10="완료","완료",IF($M10="지연","지연",IF($M10="주의","주의",IF($J10>0,"진행","계획"))))) | V10: =IF(OR($G10>'설정'!$D$11,$H10<'설정'!$C$11),"",IF($L10="완료","완료",IF($M10="지연","지연",IF($M10="주의","주의",IF($J10>0,"진행","계획"))))) | W10: =IF(OR($G10>'설정'!$D$12,$H10<'설정'!$C$12),"",IF($L10="완료","완료",IF($M10="지연","지연",IF($M10="주의","주의",IF($J10>0,"진행","계획")))))
A11: WBS-010 | B11: 3번 | C11: 문제풀이 | D11: 고지연 | E11: 일반 문제 10문제 세트, 답안 제출, 등록 정답 기반 채점 구현 | F11: 10문제 중 7문제 이상 통과 기준 동작 | G11: 46203 | H11: 46210 | I11: 1 | J11: 1 | K11: =IF(LEN($J11&"")=0,"",$J11) -> 1 | L11: =IF(LEN($K11&"")=0,"",IF($K11>=1,"완료",IF($K11>0,"진행","준비"))) -> 완료 | M11: =IF(OR(LEN($I11&"")=0,LEN($J11&"")=0),"",IF($J11>=1,"정상",IF($J11>=$I11,"정상",IF($I11-$J11>0.1,"지연","주의")))) -> 정상 | N11: 문제 | O11: =IF(OR($G11>'설정'!$D$4,$H11<'설정'!$C$4),"",IF($L11="완료","완료",IF($M11="지연","지연",IF($M11="주의","주의",IF($J11>0,"진행","계획"))))) | P11: =IF(OR($G11>'설정'!$D$5,$H11<'설정'!$C$5),"",IF($L11="완료","완료",IF($M11="지연","지연",IF($M11="주의","주의",IF($J11>0,"진행","계획"))))) | Q11: =IF(OR($G11>'설정'!$D$6,$H11<'설정'!$C$6),"",IF($L11="완료","완료",IF($M11="지연","지연",IF($M11="주의","주의",IF($J11>0,"진행","계획"))))) | S11: =IF(OR($G11>'설정'!$D$8,$H11<'설정'!$C$8),"",IF($L11="완료","완료",IF($M11="지연","지연",IF($M11="주의","주의",IF($J11>0,"진행","계획"))))) -> 완료 | T11: =IF(OR($G11>'설정'!$D$9,$H11<'설정'!$C$9),"",IF($L11="완료","완료",IF($M11="지연","지연",IF($M11="주의","주의",IF($J11>0,"진행","계획"))))) -> 완료 | U11: =IF(OR($G11>'설정'!$D$10,$H11<'설정'!$C$10),"",IF($L11="완료","완료",IF($M11="지연","지연",IF($M11="주의","주의",IF($J11>0,"진행","계획"))))) | V11: =IF(OR($G11>'설정'!$D$11,$H11<'설정'!$C$11),"",IF($L11="완료","완료",IF($M11="지연","지연",IF($M11="주의","주의",IF($J11>0,"진행","계획"))))) | W11: =IF(OR($G11>'설정'!$D$12,$H11<'설정'!$C$12),"",IF($L11="완료","완료",IF($M11="지연","지연",IF($M11="주의","주의",IF($J11>0,"진행","계획")))))
A12: WBS-011 | C12: 오답 복습 | E12: 오답 저장, 오답 목록/상세, 재정답, +5 1회 지급 흐름 구현 | F12: 오답 재풀이 결과와 점수 이벤트 저장 | G12: 46206 | H12: 46210 | I12: 1 | J12: 1 | K12: =IF(LEN($J12&"")=0,"",$J12) -> 1 | L12: =IF(LEN($K12&"")=0,"",IF($K12>=1,"완료",IF($K12>0,"진행","준비"))) -> 완료 | M12: =IF(OR(LEN($I12&"")=0,LEN($J12&"")=0),"",IF($J12>=1,"정상",IF($J12>=$I12,"정상",IF($I12-$J12>0.1,"지연","주의")))) -> 정상 | N12: 문제 | O12: =IF(OR($G12>'설정'!$D$4,$H12<'설정'!$C$4),"",IF($L12="완료","완료",IF($M12="지연","지연",IF($M12="주의","주의",IF($J12>0,"진행","계획"))))) | P12: =IF(OR($G12>'설정'!$D$5,$H12<'설정'!$C$5),"",IF($L12="완료","완료",IF($M12="지연","지연",IF($M12="주의","주의",IF($J12>0,"진행","계획"))))) | Q12: =IF(OR($G12>'설정'!$D$6,$H12<'설정'!$C$6),"",IF($L12="완료","완료",IF($M12="지연","지연",IF($M12="주의","주의",IF($J12>0,"진행","계획"))))) | R12: =IF(OR($G12>'설정'!$D$7,$H12<'설정'!$C$7),"",IF($L12="완료","완료",IF($M12="지연","지연",IF($M12="주의","주의",IF($J12>0,"진행","계획"))))) | S12: =IF(OR($G12>'설정'!$D$8,$H12<'설정'!$C$8),"",IF($L12="완료","완료",IF($M12="지연","지연",IF($M12="주의","주의",IF($J12>0,"진행","계획"))))) -> 완료 | T12: =IF(OR($G12>'설정'!$D$9,$H12<'설정'!$C$9),"",IF($L12="완료","완료",IF($M12="지연","지연",IF($M12="주의","주의",IF($J12>0,"진행","계획"))))) -> 완료 | U12: =IF(OR($G12>'설정'!$D$10,$H12<'설정'!$C$10),"",IF($L12="완료","완료",IF($M12="지연","지연",IF($M12="주의","주의",IF($J12>0,"진행","계획"))))) | V12: =IF(OR($G12>'설정'!$D$11,$H12<'설정'!$C$11),"",IF($L12="완료","완료",IF($M12="지연","지연",IF($M12="주의","주의",IF($J12>0,"진행","계획"))))) | W12: =IF(OR($G12>'설정'!$D$12,$H12<'설정'!$C$12),"",IF($L12="완료","완료",IF($M12="지연","지연",IF($M12="주의","주의",IF($J12>0,"진행","계획")))))
A13: WBS-012 | C13: 점수 / 랭킹 | E13: score_events 기반 ranking 조회 구현 및 출석 점수 제외 | F13: ranking이 문제/시험 점수 기준으로 조회 | G13: 46211 | H13: 46214 | I13: 1 | J13: 1 | K13: =IF(LEN($J13&"")=0,"",$J13) -> 1 | L13: =IF(LEN($K13&"")=0,"",IF($K13>=1,"완료",IF($K13>0,"진행","준비"))) -> 완료 | M13: =IF(OR(LEN($I13&"")=0,LEN($J13&"")=0),"",IF($J13>=1,"정상",IF($J13>=$I13,"정상",IF($I13-$J13>0.1,"지연","주의")))) -> 정상 | N13: 문제 | O13: =IF(OR($G13>'설정'!$D$4,$H13<'설정'!$C$4),"",IF($L13="완료","완료",IF($M13="지연","지연",IF($M13="주의","주의",IF($J13>0,"진행","계획"))))) | P13: =IF(OR($G13>'설정'!$D$5,$H13<'설정'!$C$5),"",IF($L13="완료","완료",IF($M13="지연","지연",IF($M13="주의","주의",IF($J13>0,"진행","계획"))))) | Q13: =IF(OR($G13>'설정'!$D$6,$H13<'설정'!$C$6),"",IF($L13="완료","완료",IF($M13="지연","지연",IF($M13="주의","주의",IF($J13>0,"진행","계획"))))) | R13: =IF(OR($G13>'설정'!$D$7,$H13<'설정'!$C$7),"",IF($L13="완료","완료",IF($M13="지연","지연",IF($M13="주의","주의",IF($J13>0,"진행","계획"))))) | S13: =IF(OR($G13>'설정'!$D$8,$H13<'설정'!$C$8),"",IF($L13="완료","완료",IF($M13="지연","지연",IF($M13="주의","주의",IF($J13>0,"진행","계획"))))) | T13: =IF(OR($G13>'설정'!$D$9,$H13<'설정'!$C$9),"",IF($L13="완료","완료",IF($M13="지연","지연",IF($M13="주의","주의",IF($J13>0,"진행","계획"))))) -> 완료 | U13: =IF(OR($G13>'설정'!$D$10,$H13<'설정'!$C$10),"",IF($L13="완료","완료",IF($M13="지연","지연",IF($M13="주의","주의",IF($J13>0,"진행","계획"))))) | V13: =IF(OR($G13>'설정'!$D$11,$H13<'설정'!$C$11),"",IF($L13="완료","완료",IF($M13="지연","지연",IF($M13="주의","주의",IF($J13>0,"진행","계획"))))) | W13: =IF(OR($G13>'설정'!$D$12,$H13<'설정'!$C$12),"",IF($L13="완료","완료",IF($M13="지연","지연",IF($M13="주의","주의",IF($J13>0,"진행","계획")))))
A14: WBS-013 | B14: 4번 | C14: AI 코딩테스트 | D14: 이현겸 | E14: 시험 eligibility, session/status, 답안 저장, retry 흐름 구현 | F14: SR-008 시험 응시와 결과 흐름 route/API/MVC 연결 | G14: 46202 | H14: 46204 | I14: 1 | J14: 1 | K14: =IF(LEN($J14&"")=0,"",$J14) -> 1 | L14: =IF(LEN($K14&"")=0,"",IF($K14>=1,"완료",IF($K14>0,"진행","준비"))) -> 완료 | M14: =IF(OR(LEN($I14&"")=0,LEN($J14&"")=0),"",IF($J14>=1,"정상",IF($J14>=$I14,"정상",IF($I14-$J14>0.1,"지연","주의")))) -> 정상 | N14: AI | O14: =IF(OR($G14>'설정'!$D$4,$H14<'설정'!$C$4),"",IF($L14="완료","완료",IF($M14="지연","지연",IF($M14="주의","주의",IF($J14>0,"진행","계획"))))) | P14: =IF(OR($G14>'설정'!$D$5,$H14<'설정'!$C$5),"",IF($L14="완료","완료",IF($M14="지연","지연",IF($M14="주의","주의",IF($J14>0,"진행","계획"))))) | Q14: =IF(OR($G14>'설정'!$D$6,$H14<'설정'!$C$6),"",IF($L14="완료","완료",IF($M14="지연","지연",IF($M14="주의","주의",IF($J14>0,"진행","계획"))))) | R14: =IF(OR($G14>'설정'!$D$7,$H14<'설정'!$C$7),"",IF($L14="완료","완료",IF($M14="지연","지연",IF($M14="주의","주의",IF($J14>0,"진행","계획"))))) -> 완료 | S14: =IF(OR($G14>'설정'!$D$8,$H14<'설정'!$C$8),"",IF($L14="완료","완료",IF($M14="지연","지연",IF($M14="주의","주의",IF($J14>0,"진행","계획"))))) -> 완료 | T14: =IF(OR($G14>'설정'!$D$9,$H14<'설정'!$C$9),"",IF($L14="완료","완료",IF($M14="지연","지연",IF($M14="주의","주의",IF($J14>0,"진행","계획"))))) | U14: =IF(OR($G14>'설정'!$D$10,$H14<'설정'!$C$10),"",IF($L14="완료","완료",IF($M14="지연","지연",IF($M14="주의","주의",IF($J14>0,"진행","계획"))))) | V14: =IF(OR($G14>'설정'!$D$11,$H14<'설정'!$C$11),"",IF($L14="완료","완료",IF($M14="지연","지연",IF($M14="주의","주의",IF($J14>0,"진행","계획"))))) | W14: =IF(OR($G14>'설정'!$D$12,$H14<'설정'!$C$12),"",IF($L14="완료","완료",IF($M14="지연","지연",IF($M14="주의","주의",IF($J14>0,"진행","계획")))))
A15: WBS-014 | C15: ChatGPT API | E15: ChatGPT API adapter, prompt schema, request log, timeout/retry 기준 구현 | F15: 로컬 LLM 없이 ChatGPT API 호출 성공/실패 기록 | G15: 46203 | H15: 46205 | I15: 1 | J15: 1 | K15: =IF(LEN($J15&"")=0,"",$J15) -> 1 | L15: =IF(LEN($K15&"")=0,"",IF($K15>=1,"완료",IF($K15>0,"진행","준비"))) -> 완료 | M15: =IF(OR(LEN($I15&"")=0,LEN($J15&"")=0),"",IF($J15>=1,"정상",IF($J15>=$I15,"정상",IF($I15-$J15>0.1,"지연","주의")))) -> 정상 | N15: AI | O15: =IF(OR($G15>'설정'!$D$4,$H15<'설정'!$C$4),"",IF($L15="완료","완료",IF($M15="지연","지연",IF($M15="주의","주의",IF($J15>0,"진행","계획"))))) | P15: =IF(OR($G15>'설정'!$D$5,$H15<'설정'!$C$5),"",IF($L15="완료","완료",IF($M15="지연","지연",IF($M15="주의","주의",IF($J15>0,"진행","계획"))))) | Q15: =IF(OR($G15>'설정'!$D$6,$H15<'설정'!$C$6),"",IF($L15="완료","완료",IF($M15="지연","지연",IF($M15="주의","주의",IF($J15>0,"진행","계획"))))) | R15: =IF(OR($G15>'설정'!$D$7,$H15<'설정'!$C$7),"",IF($L15="완료","완료",IF($M15="지연","지연",IF($M15="주의","주의",IF($J15>0,"진행","계획"))))) -> 완료 | S15: =IF(OR($G15>'설정'!$D$8,$H15<'설정'!$C$8),"",IF($L15="완료","완료",IF($M15="지연","지연",IF($M15="주의","주의",IF($J15>0,"진행","계획"))))) -> 완료 | T15: =IF(OR($G15>'설정'!$D$9,$H15<'설정'!$C$9),"",IF($L15="완료","완료",IF($M15="지연","지연",IF($M15="주의","주의",IF($J15>0,"진행","계획"))))) | U15: =IF(OR($G15>'설정'!$D$10,$H15<'설정'!$C$10),"",IF($L15="완료","완료",IF($M15="지연","지연",IF($M15="주의","주의",IF($J15>0,"진행","계획"))))) | V15: =IF(OR($G15>'설정'!$D$11,$H15<'설정'!$C$11),"",IF($L15="완료","완료",IF($M15="지연","지연",IF($M15="주의","주의",IF($J15>0,"진행","계획"))))) | W15: =IF(OR($G15>'설정'!$D$12,$H15<'설정'!$C$12),"",IF($L15="완료","완료",IF($M15="지연","지연",IF($M15="주의","주의",IF($J15>0,"진행","계획")))))
A16: WBS-015 | C16: 테스트케이스 실행 채점 | E16: AI는 생성/해설/코드 리뷰만 담당하고 정답 판정은 testcase 실행으로 처리 | F16: 정답/오답 판정이 testcase 실행 결과로 저장 | G16: 46204 | H16: 46206 | I16: 1 | J16: 1 | K16: =IF(LEN($J16&"")=0,"",$J16) -> 1 | L16: =IF(LEN($K16&"")=0,"",IF($K16>=1,"완료",IF($K16>0,"진행","준비"))) -> 완료 | M16: =IF(OR(LEN($I16&"")=0,LEN($J16&"")=0),"",IF($J16>=1,"정상",IF($J16>=$I16,"정상",IF($I16-$J16>0.1,"지연","주의")))) -> 정상 | N16: AI | O16: =IF(OR($G16>'설정'!$D$4,$H16<'설정'!$C$4),"",IF($L16="완료","완료",IF($M16="지연","지연",IF($M16="주의","주의",IF($J16>0,"진행","계획"))))) | P16: =IF(OR($G16>'설정'!$D$5,$H16<'설정'!$C$5),"",IF($L16="완료","완료",IF($M16="지연","지연",IF($M16="주의","주의",IF($J16>0,"진행","계획"))))) | Q16: =IF(OR($G16>'설정'!$D$6,$H16<'설정'!$C$6),"",IF($L16="완료","완료",IF($M16="지연","지연",IF($M16="주의","주의",IF($J16>0,"진행","계획"))))) | R16: =IF(OR($G16>'설정'!$D$7,$H16<'설정'!$C$7),"",IF($L16="완료","완료",IF($M16="지연","지연",IF($M16="주의","주의",IF($J16>0,"진행","계획"))))) | S16: =IF(OR($G16>'설정'!$D$8,$H16<'설정'!$C$8),"",IF($L16="완료","완료",IF($M16="지연","지연",IF($M16="주의","주의",IF($J16>0,"진행","계획"))))) -> 완료 | T16: =IF(OR($G16>'설정'!$D$9,$H16<'설정'!$C$9),"",IF($L16="완료","완료",IF($M16="지연","지연",IF($M16="주의","주의",IF($J16>0,"진행","계획"))))) | U16: =IF(OR($G16>'설정'!$D$10,$H16<'설정'!$C$10),"",IF($L16="완료","완료",IF($M16="지연","지연",IF($M16="주의","주의",IF($J16>0,"진행","계획"))))) | V16: =IF(OR($G16>'설정'!$D$11,$H16<'설정'!$C$11),"",IF($L16="완료","완료",IF($M16="지연","지연",IF($M16="주의","주의",IF($J16>0,"진행","계획"))))) | W16: =IF(OR($G16>'설정'!$D$12,$H16<'설정'!$C$12),"",IF($L16="완료","완료",IF($M16="지연","지연",IF($M16="주의","주의",IF($J16>0,"진행","계획")))))
A17: WBS-016 | C17: AI 분석 MVP | E17: 무료 분석 화면 DB 연결, Premium 상세 그래프/카드, 분석 상태, 실패/재시도 흐름 구현·수정 | F17: 무료/프리미엄 분석 화면이 실제 시험·학습·오답 데이터로 표시되고 Premium 접근이 PaymentAccessService 기준으로 제어됨 | G17: 46206 | H17: 46214 | I17: 1 | J17: 1 | K17: =IF(LEN($J17&"")=0,"",$J17) -> 1 | L17: =IF(LEN($K17&"")=0,"",IF($K17>=1,"완료",IF($K17>0,"진행","준비"))) -> 완료 | M17: =IF(OR(LEN($I17&"")=0,LEN($J17&"")=0),"",IF($J17>=1,"정상",IF($J17>=$I17,"정상",IF($I17-$J17>0.1,"지연","주의")))) -> 정상 | N17: MVP | O17: =IF(OR($G17>'설정'!$D$4,$H17<'설정'!$C$4),"",IF($L17="완료","완료",IF($M17="지연","지연",IF($M17="주의","주의",IF($J17>0,"진행","계획"))))) | P17: =IF(OR($G17>'설정'!$D$5,$H17<'설정'!$C$5),"",IF($L17="완료","완료",IF($M17="지연","지연",IF($M17="주의","주의",IF($J17>0,"진행","계획"))))) | Q17: =IF(OR($G17>'설정'!$D$6,$H17<'설정'!$C$6),"",IF($L17="완료","완료",IF($M17="지연","지연",IF($M17="주의","주의",IF($J17>0,"진행","계획"))))) | R17: =IF(OR($G17>'설정'!$D$7,$H17<'설정'!$C$7),"",IF($L17="완료","완료",IF($M17="지연","지연",IF($M17="주의","주의",IF($J17>0,"진행","계획"))))) | S17: =IF(OR($G17>'설정'!$D$8,$H17<'설정'!$C$8),"",IF($L17="완료","완료",IF($M17="지연","지연",IF($M17="주의","주의",IF($J17>0,"진행","계획"))))) -> 완료 | T17: =IF(OR($G17>'설정'!$D$9,$H17<'설정'!$C$9),"",IF($L17="완료","완료",IF($M17="지연","지연",IF($M17="주의","주의",IF($J17>0,"진행","계획"))))) -> 완료 | U17: =IF(OR($G17>'설정'!$D$10,$H17<'설정'!$C$10),"",IF($L17="완료","완료",IF($M17="지연","지연",IF($M17="주의","주의",IF($J17>0,"진행","계획"))))) | V17: =IF(OR($G17>'설정'!$D$11,$H17<'설정'!$C$11),"",IF($L17="완료","완료",IF($M17="지연","지연",IF($M17="주의","주의",IF($J17>0,"진행","계획")))))
A18: WBS-017 | B18: 5번 | C18: 커뮤니티 | D18: 장윤성 | E18: 게시글, 댓글, 좋아요, 스크랩, 신고 흐름 구현 | F18: owner/admin 권한 기준으로 커뮤니티 CRUD와 반응 기능 동작 | G18: 46204 | H18: 46218 | I18: 1 | J18: 0.9 | K18: =IF(LEN($J18&"")=0,"",$J18) -> 0.9 | L18: =IF(LEN($K18&"")=0,"",IF($K18>=1,"완료",IF($K18>0,"진행","준비"))) -> 진행 | M18: =IF(OR(LEN($I17&"")=0,LEN($J17&"")=0),"",IF($J17>=1,"정상",IF($J17>=$I17,"정상",IF($I17-$J17>0.1,"지연","주의")))) -> 정상 | N18: 커뮤니티 | O18: =IF(OR($G18>'설정'!$D$4,$H18<'설정'!$C$4),"",IF($L18="완료","완료",IF($M18="지연","지연",IF($M18="주의","주의",IF($J18>0,"진행","계획"))))) | P18: =IF(OR($G18>'설정'!$D$5,$H18<'설정'!$C$5),"",IF($L18="완료","완료",IF($M18="지연","지연",IF($M18="주의","주의",IF($J18>0,"진행","계획"))))) | Q18: =IF(OR($G18>'설정'!$D$6,$H18<'설정'!$C$6),"",IF($L18="완료","완료",IF($M18="지연","지연",IF($M18="주의","주의",IF($J18>0,"진행","계획"))))) | R18: =IF(OR($G18>'설정'!$D$7,$H18<'설정'!$C$7),"",IF($L18="완료","완료",IF($M18="지연","지연",IF($M18="주의","주의",IF($J18>0,"진행","계획"))))) | S18: =IF(OR($G17>'설정'!$D$8,$H17<'설정'!$C$8),"",IF($L17="완료","완료",IF($M17="지연","지연",IF($M17="주의","주의",IF($J17>0,"진행","계획"))))) -> 완료 | T18: =IF(OR($G17>'설정'!$D$8,$H17<'설정'!$C$8),"",IF($L17="완료","완료",IF($M17="지연","지연",IF($M17="주의","주의",IF($J17>0,"진행","계획"))))) -> 완료 | U18: =IF(OR($G17>'설정'!$D$8,$H17<'설정'!$C$8),"",IF($L17="완료","완료",IF($M17="지연","지연",IF($M17="주의","주의",IF($J17>0,"진행","계획"))))) -> 완료 | V18: =IF(OR($G18>'설정'!$D$11,$H18<'설정'!$C$11),"",IF($L18="완료","완료",IF($M18="지연","지연",IF($M18="주의","주의",IF($J18>0,"진행","계획"))))) | W18: =IF(OR($G18>'설정'!$D$12,$H18<'설정'!$C$12),"",IF($L18="완료","완료",IF($M18="지연","지연",IF($M18="주의","주의",IF($J18>0,"진행","계획")))))
A19: WBS-018 | C19: 첨부 파일 | E19: multipart upload, attachment metadata, 파일 제한 정책 구현 | F19: 첨부 저장/조회/삭제 기준이 커뮤니티 transaction에 맞게 동작 | G19: 46207 | H19: 46219 | I19: 1 | J19: 1 | K19: =IF(LEN($J19&"")=0,"",$J19) -> 1 | L19: =IF(LEN($K19&"")=0,"",IF($K19>=1,"완료",IF($K19>0,"진행","준비"))) -> 완료 | M19: =IF(OR(LEN($I19&"")=0,LEN($J19&"")=0),"",IF($J19>=1,"정상",IF($J19>=$I19,"정상",IF($I19-$J19>0.1,"지연","주의")))) -> 정상 | N19: 커뮤니티 | O19: =IF(OR($G19>'설정'!$D$4,$H19<'설정'!$C$4),"",IF($L19="완료","완료",IF($M19="지연","지연",IF($M19="주의","주의",IF($J19>0,"진행","계획"))))) | P19: =IF(OR($G19>'설정'!$D$5,$H19<'설정'!$C$5),"",IF($L19="완료","완료",IF($M19="지연","지연",IF($M19="주의","주의",IF($J19>0,"진행","계획"))))) | Q19: =IF(OR($G19>'설정'!$D$6,$H19<'설정'!$C$6),"",IF($L19="완료","완료",IF($M19="지연","지연",IF($M19="주의","주의",IF($J19>0,"진행","계획"))))) | R19: =IF(OR($G19>'설정'!$D$7,$H19<'설정'!$C$7),"",IF($L19="완료","완료",IF($M19="지연","지연",IF($M19="주의","주의",IF($J19>0,"진행","계획"))))) | S19: =IF(OR($G19>'설정'!$D$8,$H19<'설정'!$C$8),"",IF($L19="완료","완료",IF($M19="지연","지연",IF($M19="주의","주의",IF($J19>0,"진행","계획"))))) -> 완료 | T19: =IF(OR($G19>'설정'!$D$9,$H19<'설정'!$C$9),"",IF($L19="완료","완료",IF($M19="지연","지연",IF($M19="주의","주의",IF($J19>0,"진행","계획"))))) -> 완료 | U19: =IF(OR($G19>'설정'!$D$10,$H19<'설정'!$C$10),"",IF($L19="완료","완료",IF($M19="지연","지연",IF($M19="주의","주의",IF($J19>0,"진행","계획"))))) -> 완료 | V19: =IF(OR($G19>'설정'!$D$11,$H19<'설정'!$C$11),"",IF($L19="완료","완료",IF($M19="지연","지연",IF($M19="주의","주의",IF($J19>0,"진행","계획"))))) | W19: =IF(OR($G19>'설정'!$D$12,$H19<'설정'!$C$12),"",IF($L19="완료","완료",IF($M19="지연","지연",IF($M19="주의","주의",IF($J19>0,"진행","계획")))))
A20: WBS-019 | C20: 추천 콘텐츠 | E20: content_recommendations basic 조회와 추천 콘텐츠 route ownership 정리 | F20: 추천 콘텐츠가 결제 범위가 아니라 커뮤니티/콘텐츠 확장으로 유지 | G20: 46211 | H20: 46221 | I20: 1 | J20: 1 | K20: =IF(LEN($J20&"")=0,"",$J20) -> 1 | L20: =IF(LEN($K20&"")=0,"",IF($K20>=1,"완료",IF($K20>0,"진행","준비"))) -> 완료 | M20: =IF(OR(LEN($I20&"")=0,LEN($J20&"")=0),"",IF($J20>=1,"정상",IF($J20>=$I20,"정상",IF($I20-$J20>0.1,"지연","주의")))) -> 정상 | N20: 커뮤니티 | O20: =IF(OR($G20>'설정'!$D$4,$H20<'설정'!$C$4),"",IF($L20="완료","완료",IF($M20="지연","지연",IF($M20="주의","주의",IF($J20>0,"진행","계획"))))) | P20: =IF(OR($G20>'설정'!$D$5,$H20<'설정'!$C$5),"",IF($L20="완료","완료",IF($M20="지연","지연",IF($M20="주의","주의",IF($J20>0,"진행","계획"))))) | Q20: =IF(OR($G20>'설정'!$D$6,$H20<'설정'!$C$6),"",IF($L20="완료","완료",IF($M20="지연","지연",IF($M20="주의","주의",IF($J20>0,"진행","계획"))))) | R20: =IF(OR($G20>'설정'!$D$7,$H20<'설정'!$C$7),"",IF($L20="완료","완료",IF($M20="지연","지연",IF($M20="주의","주의",IF($J20>0,"진행","계획"))))) | S20: =IF(OR($G20>'설정'!$D$8,$H20<'설정'!$C$8),"",IF($L20="완료","완료",IF($M20="지연","지연",IF($M20="주의","주의",IF($J20>0,"진행","계획"))))) | T20: =IF(OR($G20>'설정'!$D$9,$H20<'설정'!$C$9),"",IF($L20="완료","완료",IF($M20="지연","지연",IF($M20="주의","주의",IF($J20>0,"진행","계획"))))) -> 완료 | U20: =IF(OR($G20>'설정'!$D$10,$H20<'설정'!$C$10),"",IF($L20="완료","완료",IF($M20="지연","지연",IF($M20="주의","주의",IF($J20>0,"진행","계획"))))) -> 완료 | V20: =IF(OR($G20>'설정'!$D$11,$H20<'설정'!$C$11),"",IF($L20="완료","완료",IF($M20="지연","지연",IF($M20="주의","주의",IF($J20>0,"진행","계획"))))) | W20: =IF(OR($G20>'설정'!$D$12,$H20<'설정'!$C$12),"",IF($L20="완료","완료",IF($M20="지연","지연",IF($M20="주의","주의",IF($J20>0,"진행","계획")))))
A21: WBS-020 | B21: 6번 | C21: 결제 / Premium | D21: 박세인 | E21: dummy payment, payment history, premium_grants 생성 흐름 구현 | F21: 실제 PG 없이 결제 성공 시 ACTIVE/LIFETIME grant 생성 | G21: 46202 | H21: 46206 | I21: 1 | J21: 1 | K21: =IF(LEN($J21&"")=0,"",$J21) -> 1 | L21: =IF(LEN($K21&"")=0,"",IF($K21>=1,"완료",IF($K21>0,"진행","준비"))) -> 완료 | M21: =IF(OR(LEN($I21&"")=0,LEN($J21&"")=0),"",IF($J21>=1,"정상",IF($J21>=$I21,"정상",IF($I21-$J21>0.1,"지연","주의")))) -> 정상 | N21: 결제 | O21: =IF(OR($G21>'설정'!$D$4,$H21<'설정'!$C$4),"",IF($L21="완료","완료",IF($M21="지연","지연",IF($M21="주의","주의",IF($J21>0,"진행","계획"))))) | P21: =IF(OR($G21>'설정'!$D$5,$H21<'설정'!$C$5),"",IF($L21="완료","완료",IF($M21="지연","지연",IF($M21="주의","주의",IF($J21>0,"진행","계획"))))) | Q21: =IF(OR($G21>'설정'!$D$6,$H21<'설정'!$C$6),"",IF($L21="완료","완료",IF($M21="지연","지연",IF($M21="주의","주의",IF($J21>0,"진행","계획"))))) | R21: =IF(OR($G21>'설정'!$D$7,$H21<'설정'!$C$7),"",IF($L21="완료","완료",IF($M21="지연","지연",IF($M21="주의","주의",IF($J21>0,"진행","계획"))))) -> 완료 | S21: =IF(OR($G21>'설정'!$D$8,$H21<'설정'!$C$8),"",IF($L21="완료","완료",IF($M21="지연","지연",IF($M21="주의","주의",IF($J21>0,"진행","계획"))))) -> 완료 | T21: =IF(OR($G21>'설정'!$D$9,$H21<'설정'!$C$9),"",IF($L21="완료","완료",IF($M21="지연","지연",IF($M21="주의","주의",IF($J21>0,"진행","계획"))))) | U21: =IF(OR($G21>'설정'!$D$10,$H21<'설정'!$C$10),"",IF($L21="완료","완료",IF($M21="지연","지연",IF($M21="주의","주의",IF($J21>0,"진행","계획"))))) | V21: =IF(OR($G21>'설정'!$D$11,$H21<'설정'!$C$11),"",IF($L21="완료","완료",IF($M21="지연","지연",IF($M21="주의","주의",IF($J21>0,"진행","계획"))))) | W21: =IF(OR($G21>'설정'!$D$12,$H21<'설정'!$C$12),"",IF($L21="완료","완료",IF($M21="지연","지연",IF($M21="주의","주의",IF($J21>0,"진행","계획")))))
A22: WBS-021 | C22: Premium access | E22: PaymentAccessService로 Premium 기능 접근 가능 여부 판정 | F22: Premium 전용 role 없이 grant/status로 접근 제어 | G22: 46203 | H22: 46206 | I22: 1 | J22: 1 | K22: =IF(LEN($J22&"")=0,"",$J22) -> 1 | L22: =IF(LEN($K22&"")=0,"",IF($K22>=1,"완료",IF($K22>0,"진행","준비"))) -> 완료 | M22: =IF(OR(LEN($I22&"")=0,LEN($J22&"")=0),"",IF($J22>=1,"정상",IF($J22>=$I22,"정상",IF($I22-$J22>0.1,"지연","주의")))) -> 정상 | N22: 결제 | O22: =IF(OR($G22>'설정'!$D$4,$H22<'설정'!$C$4),"",IF($L22="완료","완료",IF($M22="지연","지연",IF($M22="주의","주의",IF($J22>0,"진행","계획"))))) | P22: =IF(OR($G22>'설정'!$D$5,$H22<'설정'!$C$5),"",IF($L22="완료","완료",IF($M22="지연","지연",IF($M22="주의","주의",IF($J22>0,"진행","계획"))))) | Q22: =IF(OR($G22>'설정'!$D$6,$H22<'설정'!$C$6),"",IF($L22="완료","완료",IF($M22="지연","지연",IF($M22="주의","주의",IF($J22>0,"진행","계획"))))) | R22: =IF(OR($G22>'설정'!$D$7,$H22<'설정'!$C$7),"",IF($L22="완료","완료",IF($M22="지연","지연",IF($M22="주의","주의",IF($J22>0,"진행","계획"))))) -> 완료 | S22: =IF(OR($G22>'설정'!$D$8,$H22<'설정'!$C$8),"",IF($L22="완료","완료",IF($M22="지연","지연",IF($M22="주의","주의",IF($J22>0,"진행","계획"))))) -> 완료 | T22: =IF(OR($G22>'설정'!$D$9,$H22<'설정'!$C$9),"",IF($L22="완료","완료",IF($M22="지연","지연",IF($M22="주의","주의",IF($J22>0,"진행","계획"))))) | U22: =IF(OR($G22>'설정'!$D$10,$H22<'설정'!$C$10),"",IF($L22="완료","완료",IF($M22="지연","지연",IF($M22="주의","주의",IF($J22>0,"진행","계획"))))) | V22: =IF(OR($G22>'설정'!$D$11,$H22<'설정'!$C$11),"",IF($L22="완료","완료",IF($M22="지연","지연",IF($M22="주의","주의",IF($J22>0,"진행","계획"))))) | W22: =IF(OR($G22>'설정'!$D$12,$H22<'설정'!$C$12),"",IF($L22="완료","완료",IF($M22="지연","지연",IF($M22="주의","주의",IF($J22>0,"진행","계획")))))
A23: WBS-022 | C23: 마이페이지 / 설정 | E23: mypage, profile, security, social, system, payment, withdraw 화면/기능 구현 | F23: SR-012, SR-015 화면이 API/MVC 명세와 연결 | G23: 46204 | H23: 46215 | I23: 1 | J23: 1 | K23: =IF(LEN($J23&"")=0,"",$J23) -> 1 | L23: =IF(LEN($K23&"")=0,"",IF($K23>=1,"완료",IF($K23>0,"진행","준비"))) -> 완료 | M23: =IF(OR(LEN($I23&"")=0,LEN($J23&"")=0),"",IF($J23>=1,"정상",IF($J23>=$I23,"정상",IF($I23-$J23>0.1,"지연","주의")))) -> 정상 | N23: 사용자 | O23: =IF(OR($G23>'설정'!$D$4,$H23<'설정'!$C$4),"",IF($L23="완료","완료",IF($M23="지연","지연",IF($M23="주의","주의",IF($J23>0,"진행","계획"))))) | P23: =IF(OR($G23>'설정'!$D$5,$H23<'설정'!$C$5),"",IF($L23="완료","완료",IF($M23="지연","지연",IF($M23="주의","주의",IF($J23>0,"진행","계획"))))) | Q23: =IF(OR($G23>'설정'!$D$6,$H23<'설정'!$C$6),"",IF($L23="완료","완료",IF($M23="지연","지연",IF($M23="주의","주의",IF($J23>0,"진행","계획"))))) | R23: =IF(OR($G23>'설정'!$D$7,$H23<'설정'!$C$7),"",IF($L23="완료","완료",IF($M23="지연","지연",IF($M23="주의","주의",IF($J23>0,"진행","계획"))))) | S23: =IF(OR($G23>'설정'!$D$8,$H23<'설정'!$C$8),"",IF($L23="완료","완료",IF($M23="지연","지연",IF($M23="주의","주의",IF($J23>0,"진행","계획"))))) -> 완료 | T23: =IF(OR($G23>'설정'!$D$9,$H23<'설정'!$C$9),"",IF($L23="완료","완료",IF($M23="지연","지연",IF($M23="주의","주의",IF($J23>0,"진행","계획"))))) -> 완료 | U23: =IF(OR($G23>'설정'!$D$10,$H23<'설정'!$C$10),"",IF($L23="완료","완료",IF($M23="지연","지연",IF($M23="주의","주의",IF($J23>0,"진행","계획"))))) | V23: =IF(OR($G23>'설정'!$D$11,$H23<'설정'!$C$11),"",IF($L23="완료","완료",IF($M23="지연","지연",IF($M23="주의","주의",IF($J23>0,"진행","계획"))))) | W23: =IF(OR($G23>'설정'!$D$12,$H23<'설정'!$C$12),"",IF($L23="완료","완료",IF($M23="지연","지연",IF($M23="주의","주의",IF($J23>0,"진행","계획")))))
A24: WBS-023 | B24: 7번 | C24: 관리자 | D24: 송주창 | E24: admin dashboard, 사용자/콘텐츠/커뮤니티/신고/공지 관리 화면 구현 | F24: ROLE_ADMIN guard로 /admin/** 접근 제어 | G24: 46202 | H24: 46210 | I24: 1 | J24: 1 | K24: =IF(LEN($J24&"")=0,"",$J24) -> 1 | L24: =IF(LEN($K24&"")=0,"",IF($K24>=1,"완료",IF($K24>0,"진행","준비"))) -> 완료 | M24: =IF(OR(LEN($I24&"")=0,LEN($J24&"")=0),"",IF($J24>=1,"정상",IF($J24>=$I24,"정상",IF($I24-$J24>0.1,"지연","주의")))) -> 정상 | N24: 관리자 | O24: =IF(OR($G24>'설정'!$D$4,$H24<'설정'!$C$4),"",IF($L24="완료","완료",IF($M24="지연","지연",IF($M24="주의","주의",IF($J24>0,"진행","계획"))))) | P24: =IF(OR($G24>'설정'!$D$5,$H24<'설정'!$C$5),"",IF($L24="완료","완료",IF($M24="지연","지연",IF($M24="주의","주의",IF($J24>0,"진행","계획"))))) | Q24: =IF(OR($G24>'설정'!$D$6,$H24<'설정'!$C$6),"",IF($L24="완료","완료",IF($M24="지연","지연",IF($M24="주의","주의",IF($J24>0,"진행","계획"))))) | R24: =IF(OR($G24>'설정'!$D$7,$H24<'설정'!$C$7),"",IF($L24="완료","완료",IF($M24="지연","지연",IF($M24="주의","주의",IF($J24>0,"진행","계획"))))) -> 완료 | S24: =IF(OR($G24>'설정'!$D$8,$H24<'설정'!$C$8),"",IF($L24="완료","완료",IF($M24="지연","지연",IF($M24="주의","주의",IF($J24>0,"진행","계획"))))) -> 완료 | T24: =IF(OR($G24>'설정'!$D$9,$H24<'설정'!$C$9),"",IF($L24="완료","완료",IF($M24="지연","지연",IF($M24="주의","주의",IF($J24>0,"진행","계획"))))) -> 완료 | U24: =IF(OR($G24>'설정'!$D$10,$H24<'설정'!$C$10),"",IF($L24="완료","완료",IF($M24="지연","지연",IF($M24="주의","주의",IF($J24>0,"진행","계획"))))) | V24: =IF(OR($G24>'설정'!$D$11,$H24<'설정'!$C$11),"",IF($L24="완료","완료",IF($M24="지연","지연",IF($M24="주의","주의",IF($J24>0,"진행","계획"))))) | W24: =IF(OR($G24>'설정'!$D$12,$H24<'설정'!$C$12),"",IF($L24="완료","완료",IF($M24="지연","지연",IF($M24="주의","주의",IF($J24>0,"진행","계획")))))
A25: WBS-024 | C25: Admin operation log | E25: 관리자 상태 변경, 신고 처리, 공지 변경 시 admin_operation_logs 기록 | F25: 관리자 변경 action마다 audit log 기록 | G25: 46202 | H25: 46210 | I25: 1 | J25: 1 | K25: =IF(LEN($J25&"")=0,"",$J25) -> 1 | L25: =IF(LEN($K25&"")=0,"",IF($K25>=1,"완료",IF($K25>0,"진행","준비"))) -> 완료 | M25: =IF(OR(LEN($I25&"")=0,LEN($J25&"")=0),"",IF($J25>=1,"정상",IF($J25>=$I25,"정상",IF($I25-$J25>0.1,"지연","주의")))) -> 정상 | N25: 관리자 | O25: =IF(OR($G25>'설정'!$D$4,$H25<'설정'!$C$4),"",IF($L25="완료","완료",IF($M25="지연","지연",IF($M25="주의","주의",IF($J25>0,"진행","계획"))))) | P25: =IF(OR($G25>'설정'!$D$5,$H25<'설정'!$C$5),"",IF($L25="완료","완료",IF($M25="지연","지연",IF($M25="주의","주의",IF($J25>0,"진행","계획"))))) | Q25: =IF(OR($G25>'설정'!$D$6,$H25<'설정'!$C$6),"",IF($L25="완료","완료",IF($M25="지연","지연",IF($M25="주의","주의",IF($J25>0,"진행","계획"))))) | R25: =IF(OR($G25>'설정'!$D$7,$H25<'설정'!$C$7),"",IF($L25="완료","완료",IF($M25="지연","지연",IF($M25="주의","주의",IF($J25>0,"진행","계획"))))) -> 완료 | S25: =IF(OR($G25>'설정'!$D$8,$H25<'설정'!$C$8),"",IF($L25="완료","완료",IF($M25="지연","지연",IF($M25="주의","주의",IF($J25>0,"진행","계획"))))) -> 완료 | T25: =IF(OR($G25>'설정'!$D$9,$H25<'설정'!$C$9),"",IF($L25="완료","완료",IF($M25="지연","지연",IF($M25="주의","주의",IF($J25>0,"진행","계획"))))) -> 완료 | U25: =IF(OR($G25>'설정'!$D$10,$H25<'설정'!$C$10),"",IF($L25="완료","완료",IF($M25="지연","지연",IF($M25="주의","주의",IF($J25>0,"진행","계획"))))) | V25: =IF(OR($G25>'설정'!$D$11,$H25<'설정'!$C$11),"",IF($L25="완료","완료",IF($M25="지연","지연",IF($M25="주의","주의",IF($J25>0,"진행","계획"))))) | W25: =IF(OR($G25>'설정'!$D$12,$H25<'설정'!$C$12),"",IF($L25="완료","완료",IF($M25="지연","지연",IF($M25="주의","주의",IF($J25>0,"진행","계획")))))
A26: WBS-025 | C26: 통합 smoke | E26: 주요 route/API, Mapper XML namespace, template resolve 통합 점검 | F26: bootRun/test 결과와 주요 화면/API smoke 결과 공유 | G26: 46202 | H26: 46213 | I26: 1 | J26: 1 | K26: =IF(LEN($J26&"")=0,"",$J26) -> 1 | L26: =IF(LEN($K26&"")=0,"",IF($K26>=1,"완료",IF($K26>0,"진행","준비"))) -> 완료 | M26: =IF(OR(LEN($I26&"")=0,LEN($J26&"")=0),"",IF($J26>=1,"정상",IF($J26>=$I26,"정상",IF($I26-$J26>0.1,"지연","주의")))) -> 정상 | N26: 검증 | O26: =IF(OR($G26>'설정'!$D$4,$H26<'설정'!$C$4),"",IF($L26="완료","완료",IF($M26="지연","지연",IF($M26="주의","주의",IF($J26>0,"진행","계획"))))) | P26: =IF(OR($G26>'설정'!$D$5,$H26<'설정'!$C$5),"",IF($L26="완료","완료",IF($M26="지연","지연",IF($M26="주의","주의",IF($J26>0,"진행","계획"))))) | Q26: =IF(OR($G26>'설정'!$D$6,$H26<'설정'!$C$6),"",IF($L26="완료","완료",IF($M26="지연","지연",IF($M26="주의","주의",IF($J26>0,"진행","계획"))))) | R26: =IF(OR($G26>'설정'!$D$7,$H26<'설정'!$C$7),"",IF($L26="완료","완료",IF($M26="지연","지연",IF($M26="주의","주의",IF($J26>0,"진행","계획"))))) -> 완료 | S26: =IF(OR($G26>'설정'!$D$8,$H26<'설정'!$C$8),"",IF($L26="완료","완료",IF($M26="지연","지연",IF($M26="주의","주의",IF($J26>0,"진행","계획"))))) -> 완료 | T26: =IF(OR($G26>'설정'!$D$9,$H26<'설정'!$C$9),"",IF($L26="완료","완료",IF($M26="지연","지연",IF($M26="주의","주의",IF($J26>0,"진행","계획"))))) -> 완료 | U26: =IF(OR($G26>'설정'!$D$10,$H26<'설정'!$C$10),"",IF($L26="완료","완료",IF($M26="지연","지연",IF($M26="주의","주의",IF($J26>0,"진행","계획"))))) | V26: =IF(OR($G26>'설정'!$D$11,$H26<'설정'!$C$11),"",IF($L26="완료","완료",IF($M26="지연","지연",IF($M26="주의","주의",IF($J26>0,"진행","계획"))))) | W26: =IF(OR($G26>'설정'!$D$12,$H26<'설정'!$C$12),"",IF($L26="완료","완료",IF($M26="지연","지연",IF($M26="주의","주의",IF($J26>0,"진행","계획")))))
A27: WBS-026 | B27: 전체 | C27: MVP 통합 테스트 / 구현 보강 | D27: 전체 | E27: 각 담당 범위 구현 상황에 맞춰 주요 route/API/화면 smoke test, 누락 요구사항 구현·수정, MVP 부족 범위 보강 | F27: 7/11 MVP 마감 전 핵심 흐름 smoke 결과와 blocker 정리 완료 | G27: 46202 | H27: 46214 | I27: 1 | J27: 1 | K27: =IF(LEN($J27&"")=0,"",$J27) -> 1 | L27: =IF(LEN($K27&"")=0,"",IF($K27>=1,"완료",IF($K27>0,"진행","준비"))) -> 완료 | M27: =IF(OR(LEN($I27&"")=0,LEN($J27&"")=0),"",IF($J27>=1,"정상",IF($J27>=$I27,"정상",IF($I27-$J27>0.1,"지연","주의")))) -> 정상 | N27: MVP | O27: =IF(OR($G27>'설정'!$D$4,$H27<'설정'!$C$4),"",IF($L27="완료","완료",IF($M27="지연","지연",IF($M27="주의","주의",IF($J27>0,"진행","계획"))))) | P27: =IF(OR($G27>'설정'!$D$5,$H27<'설정'!$C$5),"",IF($L27="완료","완료",IF($M27="지연","지연",IF($M27="주의","주의",IF($J27>0,"진행","계획"))))) | Q27: =IF(OR($G27>'설정'!$D$6,$H27<'설정'!$C$6),"",IF($L27="완료","완료",IF($M27="지연","지연",IF($M27="주의","주의",IF($J27>0,"진행","계획"))))) | R27: =IF(OR($G27>'설정'!$D$7,$H27<'설정'!$C$7),"",IF($L27="완료","완료",IF($M27="지연","지연",IF($M27="주의","주의",IF($J27>0,"진행","계획"))))) -> 완료 | S27: =IF(OR($G27>'설정'!$D$8,$H27<'설정'!$C$8),"",IF($L27="완료","완료",IF($M27="지연","지연",IF($M27="주의","주의",IF($J27>0,"진행","계획"))))) -> 완료 | T27: =IF(OR($G27>'설정'!$D$9,$H27<'설정'!$C$9),"",IF($L27="완료","완료",IF($M27="지연","지연",IF($M27="주의","주의",IF($J27>0,"진행","계획"))))) -> 완료 | U27: =IF(OR($G27>'설정'!$D$10,$H27<'설정'!$C$10),"",IF($L27="완료","완료",IF($M27="지연","지연",IF($M27="주의","주의",IF($J27>0,"진행","계획"))))) | V27: =IF(OR($G27>'설정'!$D$11,$H27<'설정'!$C$11),"",IF($L27="완료","완료",IF($M27="지연","지연",IF($M27="주의","주의",IF($J27>0,"진행","계획"))))) | W27: =IF(OR($G27>'설정'!$D$12,$H27<'설정'!$C$12),"",IF($L27="완료","완료",IF($M27="지연","지연",IF($M27="주의","주의",IF($J27>0,"진행","계획")))))
A28: WBS-027 | B28: MVP 이후 | C28: 확장 기능 / 애니메이션 / 배포 준비 | D28: 전체 | E28: MVP 이후 확장 기능 구현, 화면 애니메이션 적용, MVP 미흡 기능 추가 보강, 배포 준비 체크리스트 완료 | F28: 7/18까지 확장 기능·애니메이션 적용 범위와 배포 준비 상태가 정리됨 | G28: 46214 | H28: 46221 | I28: 1 | J28: 1 | K28: =IF(LEN($J28&"")=0,"",$J28) -> 1 | L28: =IF(LEN($K28&"")=0,"",IF($K28>=1,"완료",IF($K28>0,"진행","준비"))) -> 완료 | M28: =IF(OR(LEN($I28&"")=0,LEN($J28&"")=0),"",IF($J28>=1,"정상",IF($J28>=$I28,"정상",IF($I28-$J28>0.1,"지연","주의")))) -> 정상 | N28: 확장 | O28: =IF(OR($G28>'설정'!$D$4,$H28<'설정'!$C$4),"",IF($L28="완료","완료",IF($M28="지연","지연",IF($M28="주의","주의",IF($J28>0,"진행","계획"))))) | P28: =IF(OR($G28>'설정'!$D$5,$H28<'설정'!$C$5),"",IF($L28="완료","완료",IF($M28="지연","지연",IF($M28="주의","주의",IF($J28>0,"진행","계획"))))) | Q28: =IF(OR($G28>'설정'!$D$6,$H28<'설정'!$C$6),"",IF($L28="완료","완료",IF($M28="지연","지연",IF($M28="주의","주의",IF($J28>0,"진행","계획"))))) | R28: =IF(OR($G28>'설정'!$D$7,$H28<'설정'!$C$7),"",IF($L28="완료","완료",IF($M28="지연","지연",IF($M28="주의","주의",IF($J28>0,"진행","계획"))))) | S28: =IF(OR($G28>'설정'!$D$8,$H28<'설정'!$C$8),"",IF($L28="완료","완료",IF($M28="지연","지연",IF($M28="주의","주의",IF($J28>0,"진행","계획"))))) | T28: =IF(OR($G28>'설정'!$D$9,$H28<'설정'!$C$9),"",IF($L28="완료","완료",IF($M28="지연","지연",IF($M28="주의","주의",IF($J28>0,"진행","계획"))))) -> 완료 | U28: =IF(OR($G28>'설정'!$D$10,$H28<'설정'!$C$10),"",IF($L28="완료","완료",IF($M28="지연","지연",IF($M28="주의","주의",IF($J28>0,"진행","계획"))))) -> 완료 | V28: =IF(OR($G28>'설정'!$D$11,$H28<'설정'!$C$11),"",IF($L28="완료","완료",IF($M28="지연","지연",IF($M28="주의","주의",IF($J28>0,"진행","계획"))))) | W28: =IF(OR($G28>'설정'!$D$12,$H28<'설정'!$C$12),"",IF($L28="완료","완료",IF($M28="지연","지연",IF($M28="주의","주의",IF($J28>0,"진행","계획")))))
A29: WBS-028 | C29: 공통 UI / Theme | D29: 전체 | E29: 다크모드 버튼 텍스트 가독성 개선 및 Theme 대비 점검 | F29: 다크모드가 적용된 전체 화면에서 버튼 텍스트 대비가 기준 충족 | G29: 46214 | H29: 46221 | I29: 1 | J29: 1 | K29: =IF(LEN($J29&"")=0,"",$J29) -> 1 | L29: =IF(LEN($K29&"")=0,"",IF($K29>=1,"완료",IF($K29>0,"진행","준비"))) -> 완료 | M29: =IF(OR(LEN($I29&"")=0,LEN($J29&"")=0),"",IF($J29>=1,"정상",IF($J29>=$I29,"정상",IF($I29-$J29>0.1,"지연","주의")))) -> 정상 | N29: 공통 UI | O29: =IF(OR($G29>'설정'!$D$4,$H29<'설정'!$C$4),"",IF($L29="완료","완료",IF($M29="지연","지연",IF($M29="주의","주의",IF($J29>0,"진행","계획"))))) | P29: =IF(OR($G29>'설정'!$D$5,$H29<'설정'!$C$5),"",IF($L29="완료","완료",IF($M29="지연","지연",IF($M29="주의","주의",IF($J29>0,"진행","계획"))))) | Q29: =IF(OR($G29>'설정'!$D$6,$H29<'설정'!$C$6),"",IF($L29="완료","완료",IF($M29="지연","지연",IF($M29="주의","주의",IF($J29>0,"진행","계획"))))) | R29: =IF(OR($G29>'설정'!$D$7,$H29<'설정'!$C$7),"",IF($L29="완료","완료",IF($M29="지연","지연",IF($M29="주의","주의",IF($J29>0,"진행","계획"))))) | S29: =IF(OR($G29>'설정'!$D$8,$H29<'설정'!$C$8),"",IF($L29="완료","완료",IF($M29="지연","지연",IF($M29="주의","주의",IF($J29>0,"진행","계획"))))) | T29: =IF(OR($G29>'설정'!$D$9,$H29<'설정'!$C$9),"",IF($L29="완료","완료",IF($M29="지연","지연",IF($M29="주의","주의",IF($J29>0,"진행","계획"))))) -> 완료 | U29: =IF(OR($G29>'설정'!$D$10,$H29<'설정'!$C$10),"",IF($L29="완료","완료",IF($M29="지연","지연",IF($M29="주의","주의",IF($J29>0,"진행","계획"))))) -> 완료 | V29: =IF(OR($G29>'설정'!$D$11,$H29<'설정'!$C$11),"",IF($L29="완료","완료",IF($M29="지연","지연",IF($M29="주의","주의",IF($J29>0,"진행","계획"))))) | W29: =IF(OR($G29>'설정'!$D$12,$H29<'설정'!$C$12),"",IF($L29="완료","완료",IF($M29="지연","지연",IF($M29="주의","주의",IF($J29>0,"진행","계획")))))
A30: WBS-029 | C30: 공통 기반 / 배포·운영 준비 | D30: 이현겸 | E30: 배포 흐름·운영 환경변수·smoke test·문서/추적표 통합 정리 | F30: 배포·운영 기준, 추적표·문서와 발표 전 통합 검증이 최신화됨 | G30: 46214 | H30: 46221 | I30: 1 | J30: 1 | K30: =IF(LEN($J30&"")=0,"",$J30) -> 1 | L30: =IF(LEN($K30&"")=0,"",IF($K30>=1,"완료",IF($K30>0,"진행","준비"))) -> 완료 | M30: =IF(OR(LEN($I30&"")=0,LEN($J30&"")=0),"",IF($J30>=1,"정상",IF($J30>=$I30,"정상",IF($I30-$J30>0.1,"지연","주의")))) -> 정상 | N30: 공통/배포 | O30: =IF(OR($G30>'설정'!$D$4,$H30<'설정'!$C$4),"",IF($L30="완료","완료",IF($M30="지연","지연",IF($M30="주의","주의",IF($J30>0,"진행","계획"))))) | P30: =IF(OR($G30>'설정'!$D$5,$H30<'설정'!$C$5),"",IF($L30="완료","완료",IF($M30="지연","지연",IF($M30="주의","주의",IF($J30>0,"진행","계획"))))) | Q30: =IF(OR($G30>'설정'!$D$6,$H30<'설정'!$C$6),"",IF($L30="완료","완료",IF($M30="지연","지연",IF($M30="주의","주의",IF($J30>0,"진행","계획"))))) | R30: =IF(OR($G30>'설정'!$D$7,$H30<'설정'!$C$7),"",IF($L30="완료","완료",IF($M30="지연","지연",IF($M30="주의","주의",IF($J30>0,"진행","계획"))))) | S30: =IF(OR($G30>'설정'!$D$8,$H30<'설정'!$C$8),"",IF($L30="완료","완료",IF($M30="지연","지연",IF($M30="주의","주의",IF($J30>0,"진행","계획"))))) | T30: =IF(OR($G30>'설정'!$D$9,$H30<'설정'!$C$9),"",IF($L30="완료","완료",IF($M30="지연","지연",IF($M30="주의","주의",IF($J30>0,"진행","계획"))))) -> 완료 | U30: =IF(OR($G30>'설정'!$D$10,$H30<'설정'!$C$10),"",IF($L30="완료","완료",IF($M30="지연","지연",IF($M30="주의","주의",IF($J30>0,"진행","계획"))))) -> 완료 | V30: =IF(OR($G30>'설정'!$D$11,$H30<'설정'!$C$11),"",IF($L30="완료","완료",IF($M30="지연","지연",IF($M30="주의","주의",IF($J30>0,"진행","계획"))))) | W30: =IF(OR($G30>'설정'!$D$12,$H30<'설정'!$C$12),"",IF($L30="완료","완료",IF($M30="지연","지연",IF($M30="주의","주의",IF($J30>0,"진행","계획")))))
A31: WBS-030 | C31: 학습·커리큘럼·출석 | D31: 조아진 | E31: 과목 대표 정보·진도율 개선, 레벨·행성 달성 연출, 누비 행성 이동 애니메이션 | F31: 학습 흐름에서 대표 정보·진도와 완료·누비 이동 연출이 확인됨 | G31: 46214 | H31: 46221 | I31: 1 | J31: 1 | K31: =IF(LEN($J31&"")=0,"",$J31) -> 1 | L31: =IF(LEN($K31&"")=0,"",IF($K31>=1,"완료",IF($K31>0,"진행","준비"))) -> 완료 | M31: =IF(OR(LEN($I31&"")=0,LEN($J31&"")=0),"",IF($J31>=1,"정상",IF($J31>=$I31,"정상",IF($I31-$J31>0.1,"지연","주의")))) -> 정상 | N31: 학습 | O31: =IF(OR($G31>'설정'!$D$4,$H31<'설정'!$C$4),"",IF($L31="완료","완료",IF($M31="지연","지연",IF($M31="주의","주의",IF($J31>0,"진행","계획"))))) | P31: =IF(OR($G31>'설정'!$D$5,$H31<'설정'!$C$5),"",IF($L31="완료","완료",IF($M31="지연","지연",IF($M31="주의","주의",IF($J31>0,"진행","계획"))))) | Q31: =IF(OR($G31>'설정'!$D$6,$H31<'설정'!$C$6),"",IF($L31="완료","완료",IF($M31="지연","지연",IF($M31="주의","주의",IF($J31>0,"진행","계획"))))) | R31: =IF(OR($G31>'설정'!$D$7,$H31<'설정'!$C$7),"",IF($L31="완료","완료",IF($M31="지연","지연",IF($M31="주의","주의",IF($J31>0,"진행","계획"))))) | S31: =IF(OR($G31>'설정'!$D$8,$H31<'설정'!$C$8),"",IF($L31="완료","완료",IF($M31="지연","지연",IF($M31="주의","주의",IF($J31>0,"진행","계획"))))) | T31: =IF(OR($G31>'설정'!$D$9,$H31<'설정'!$C$9),"",IF($L31="완료","완료",IF($M31="지연","지연",IF($M31="주의","주의",IF($J31>0,"진행","계획"))))) -> 완료 | U31: =IF(OR($G31>'설정'!$D$10,$H31<'설정'!$C$10),"",IF($L31="완료","완료",IF($M31="지연","지연",IF($M31="주의","주의",IF($J31>0,"진행","계획"))))) -> 완료 | V31: =IF(OR($G31>'설정'!$D$11,$H31<'설정'!$C$11),"",IF($L31="완료","완료",IF($M31="지연","지연",IF($M31="주의","주의",IF($J31>0,"진행","계획"))))) | W31: =IF(OR($G31>'설정'!$D$12,$H31<'설정'!$C$12),"",IF($L31="완료","완료",IF($M31="지연","지연",IF($M31="주의","주의",IF($J31>0,"진행","계획")))))
A32: WBS-031 | C32: 학습·과목 선택 | D32: 조아진 | E32: 최초 접속 시 과목 선택 화면 제공, 학습 메인 과목 선택 섹션에 과목 추가 기능 구현, 중복 추가 방지 | F32: 신규 계정이 1개 이상 과목을 선택해 진입하고 선택 과목이 학습 목록·로드맵에 반영되며 미선택·중복 과목 접근이 제한됨 | G32: 46214 | H32: 46221 | I32: 1 | J32: 1 | K32: 1 | L32: 완료 | M32: 정상 | N32: 학습 | O32: =IF(OR($G32>'설정'!$D$4,$H32<'설정'!$C$4),"",IF($L32="완료","완료",IF($M32="지연","지연",IF($M32="주의","주의",IF($J32>0,"진행","계획"))))) | P32: =IF(OR($G32>'설정'!$D$5,$H32<'설정'!$C$5),"",IF($L32="완료","완료",IF($M32="지연","지연",IF($M32="주의","주의",IF($J32>0,"진행","계획"))))) | Q32: =IF(OR($G32>'설정'!$D$6,$H32<'설정'!$C$6),"",IF($L32="완료","완료",IF($M32="지연","지연",IF($M32="주의","주의",IF($J32>0,"진행","계획"))))) | R32: =IF(OR($G32>'설정'!$D$7,$H32<'설정'!$C$7),"",IF($L32="완료","완료",IF($M32="지연","지연",IF($M32="주의","주의",IF($J32>0,"진행","계획"))))) | S32: =IF(OR($G32>'설정'!$D$8,$H32<'설정'!$C$8),"",IF($L32="완료","완료",IF($M32="지연","지연",IF($M32="주의","주의",IF($J32>0,"진행","계획"))))) | T32: =IF(OR($G32>'설정'!$D$9,$H32<'설정'!$C$9),"",IF($L32="완료","완료",IF($M32="지연","지연",IF($M32="주의","주의",IF($J32>0,"진행","계획"))))) -> 완료 | U32: =IF(OR($G32>'설정'!$D$10,$H32<'설정'!$C$10),"",IF($L32="완료","완료",IF($M32="지연","지연",IF($M32="주의","주의",IF($J32>0,"진행","계획"))))) -> 완료 | V32: =IF(OR($G32>'설정'!$D$11,$H32<'설정'!$C$11),"",IF($L32="완료","완료",IF($M32="지연","지연",IF($M32="주의","주의",IF($J32>0,"진행","계획"))))) | W32: =IF(OR($G32>'설정'!$D$12,$H32<'설정'!$C$12),"",IF($L32="완료","완료",IF($M32="지연","지연",IF($M32="주의","주의",IF($J32>0,"진행","계획")))))
A33: WBS-032 | C33: 문제풀이·오답·랭킹 | D33: 고지연 | E33: 문제 이동 버튼, 주간·월간 랭킹, 상황별 오답 피드백 | F33: 문제풀이 조작·랭킹·오답 피드백이 각 화면에서 확인됨 | G33: 46214 | H33: 46221 | I33: 1 | J33: 1 | K33: =IF(LEN($J33&"")=0,"",$J33) -> 1 | L33: =IF(LEN($K33&"")=0,"",IF($K33>=1,"완료",IF($K33>0,"진행","준비"))) -> 완료 | M33: =IF(OR(LEN($I33&"")=0,LEN($J33&"")=0),"",IF($J33>=1,"정상",IF($J33>=$I33,"정상",IF($I33-$J33>0.1,"지연","주의")))) -> 정상 | N33: 문제풀이 | O33: =IF(OR($G33>'설정'!$D$4,$H33<'설정'!$C$4),"",IF($L33="완료","완료",IF($M33="지연","지연",IF($M33="주의","주의",IF($J33>0,"진행","계획"))))) | P33: =IF(OR($G33>'설정'!$D$5,$H33<'설정'!$C$5),"",IF($L33="완료","완료",IF($M33="지연","지연",IF($M33="주의","주의",IF($J33>0,"진행","계획"))))) | Q33: =IF(OR($G33>'설정'!$D$6,$H33<'설정'!$C$6),"",IF($L33="완료","완료",IF($M33="지연","지연",IF($M33="주의","주의",IF($J33>0,"진행","계획"))))) | R33: =IF(OR($G33>'설정'!$D$7,$H33<'설정'!$C$7),"",IF($L33="완료","완료",IF($M33="지연","지연",IF($M33="주의","주의",IF($J33>0,"진행","계획"))))) | S33: =IF(OR($G33>'설정'!$D$8,$H33<'설정'!$C$8),"",IF($L33="완료","완료",IF($M33="지연","지연",IF($M33="주의","주의",IF($J33>0,"진행","계획"))))) | T33: =IF(OR($G33>'설정'!$D$9,$H33<'설정'!$C$9),"",IF($L33="완료","완료",IF($M33="지연","지연",IF($M33="주의","주의",IF($J33>0,"진행","계획"))))) -> 완료 | U33: =IF(OR($G33>'설정'!$D$10,$H33<'설정'!$C$10),"",IF($L33="완료","완료",IF($M33="지연","지연",IF($M33="주의","주의",IF($J33>0,"진행","계획"))))) -> 완료 | V33: =IF(OR($G33>'설정'!$D$11,$H33<'설정'!$C$11),"",IF($L33="완료","완료",IF($M33="지연","지연",IF($M33="주의","주의",IF($J33>0,"진행","계획"))))) | W33: =IF(OR($G33>'설정'!$D$12,$H33<'설정'!$C$12),"",IF($L33="완료","완료",IF($M33="지연","지연",IF($M33="주의","주의",IF($J33>0,"진행","계획")))))
A34: WBS-033 | C34: 문제풀이·진행 연동 | D34: 조아진 | E34: 신규 계정 첫 Bronze 레슨의 이론 완료 잠금 오류 해결, 문제풀이 시작 및 레슨 진행 상태 갱신 연동 | F34: 첫 Bronze 이론 완료 후 START_PRACTICE로 진입하고 진행 상태가 반영되며 미해금 Silver·Gold 제한은 유지됨 | G34: 46214 | H34: 46221 | I34: 1 | J34: 1 | K34: =IF(LEN($J34&"")=0,"",$J34) -> 1 | L34: =IF(LEN($K34&"")=0,"",IF($K34>=1,"완료",IF($K34>0,"진행","준비"))) -> 완료 | M34: 정상 | N34: 문제풀이 | O34: =IF(OR($G34>'설정'!$D$4,$H34<'설정'!$C$4),"",IF($L34="완료","완료",IF($M34="지연","지연",IF($M34="주의","주의",IF($J34>0,"진행","계획"))))) | P34: =IF(OR($G34>'설정'!$D$5,$H34<'설정'!$C$5),"",IF($L34="완료","완료",IF($M34="지연","지연",IF($M34="주의","주의",IF($J34>0,"진행","계획"))))) | Q34: =IF(OR($G34>'설정'!$D$6,$H34<'설정'!$C$6),"",IF($L34="완료","완료",IF($M34="지연","지연",IF($M34="주의","주의",IF($J34>0,"진행","계획"))))) | R34: =IF(OR($G34>'설정'!$D$7,$H34<'설정'!$C$7),"",IF($L34="완료","완료",IF($M34="지연","지연",IF($M34="주의","주의",IF($J34>0,"진행","계획"))))) | S34: =IF(OR($G34>'설정'!$D$8,$H34<'설정'!$C$8),"",IF($L34="완료","완료",IF($M34="지연","지연",IF($M34="주의","주의",IF($J34>0,"진행","계획"))))) | T34: =IF(OR($G34>'설정'!$D$9,$H34<'설정'!$C$9),"",IF($L34="완료","완료",IF($M34="지연","지연",IF($M34="주의","주의",IF($J34>0,"진행","계획"))))) -> 완료 | U34: =IF(OR($G34>'설정'!$D$10,$H34<'설정'!$C$10),"",IF($L34="완료","완료",IF($M34="지연","지연",IF($M34="주의","주의",IF($J34>0,"진행","계획"))))) -> 완료 | V34: =IF(OR($G34>'설정'!$D$11,$H34<'설정'!$C$11),"",IF($L34="완료","완료",IF($M34="지연","지연",IF($M34="주의","주의",IF($J34>0,"진행","계획"))))) | W34: =IF(OR($G34>'설정'!$D$12,$H34<'설정'!$C$12),"",IF($L34="완료","완료",IF($M34="지연","지연",IF($M34="주의","주의",IF($J34>0,"진행","계획")))))
A35: WBS-034 | C35: 커뮤니티·추천 콘텐츠 | D35: 장윤성 | E35: 커뮤니티 게시판 데이터 및 과목별 영상·추가 자료 확장 | F35: 커뮤니티와 추천 콘텐츠에서 추가 데이터·자료가 표시됨 | G35: 46214 | H35: 46221 | I35: 0 | J35: 0 | K35: =IF(LEN($J35&"")=0,"",$J35) -> 0 | L35: =IF(LEN($K35&"")=0,"",IF($K35>=1,"완료",IF($K35>0,"진행","준비"))) -> 준비 | M35: =IF(OR(LEN($I35&"")=0,LEN($J35&"")=0),"",IF($J35>=1,"정상",IF($J35>=$I35,"정상",IF($I35-$J35>0.1,"지연","주의")))) -> 정상 | N35: 커뮤니티 | O35: =IF(OR($G35>'설정'!$D$4,$H35<'설정'!$C$4),"",IF($L35="완료","완료",IF($M35="지연","지연",IF($M35="주의","주의",IF($J35>0,"진행","계획"))))) | P35: =IF(OR($G35>'설정'!$D$5,$H35<'설정'!$C$5),"",IF($L35="완료","완료",IF($M35="지연","지연",IF($M35="주의","주의",IF($J35>0,"진행","계획"))))) | Q35: =IF(OR($G35>'설정'!$D$6,$H35<'설정'!$C$6),"",IF($L35="완료","완료",IF($M35="지연","지연",IF($M35="주의","주의",IF($J35>0,"진행","계획"))))) | R35: =IF(OR($G35>'설정'!$D$7,$H35<'설정'!$C$7),"",IF($L35="완료","완료",IF($M35="지연","지연",IF($M35="주의","주의",IF($J35>0,"진행","계획"))))) | S35: =IF(OR($G35>'설정'!$D$8,$H35<'설정'!$C$8),"",IF($L35="완료","완료",IF($M35="지연","지연",IF($M35="주의","주의",IF($J35>0,"진행","계획"))))) | T35: =IF(OR($G17>'설정'!$D$8,$H17<'설정'!$C$8),"",IF($L17="완료","완료",IF($M17="지연","지연",IF($M17="주의","주의",IF($J17>0,"진행","계획"))))) -> 완료 | U35: =IF(OR($G17>'설정'!$D$8,$H17<'설정'!$C$8),"",IF($L17="완료","완료",IF($M17="지연","지연",IF($M17="주의","주의",IF($J17>0,"진행","계획"))))) -> 완료 | V35: =IF(OR($G35>'설정'!$D$11,$H35<'설정'!$C$11),"",IF($L35="완료","완료",IF($M35="지연","지연",IF($M35="주의","주의",IF($J35>0,"진행","계획"))))) | W35: =IF(OR($G35>'설정'!$D$12,$H35<'설정'!$C$12),"",IF($L35="완료","완료",IF($M35="지연","지연",IF($M35="주의","주의",IF($J35>0,"진행","계획")))))
A36: WBS-035 | C36: 관리자·운영 | D36: 송주창 | E36: 통계 필터, 과목 비활성화, 공지·운영 로그, 커뮤니티 숨김 표시 | F36: 관리자 통계·운영 기능과 사용자 노출 제한 흐름이 확인됨 | G36: 46214 | H36: 46221 | I36: 1 | J36: 1 | K36: =IF(LEN($J36&"")=0,"",$J36) -> 1 | L36: =IF(LEN($K36&"")=0,"",IF($K36>=1,"완료",IF($K36>0,"진행","준비"))) -> 완료 | M36: =IF(OR(LEN($I36&"")=0,LEN($J36&"")=0),"",IF($J36>=1,"정상",IF($J36>=$I36,"정상",IF($I36-$J36>0.1,"지연","주의")))) -> 정상 | N36: 관리자 | O36: =IF(OR($G36>'설정'!$D$4,$H36<'설정'!$C$4),"",IF($L36="완료","완료",IF($M36="지연","지연",IF($M36="주의","주의",IF($J36>0,"진행","계획"))))) | P36: =IF(OR($G36>'설정'!$D$5,$H36<'설정'!$C$5),"",IF($L36="완료","완료",IF($M36="지연","지연",IF($M36="주의","주의",IF($J36>0,"진행","계획"))))) | Q36: =IF(OR($G36>'설정'!$D$6,$H36<'설정'!$C$6),"",IF($L36="완료","완료",IF($M36="지연","지연",IF($M36="주의","주의",IF($J36>0,"진행","계획"))))) | R36: =IF(OR($G36>'설정'!$D$7,$H36<'설정'!$C$7),"",IF($L36="완료","완료",IF($M36="지연","지연",IF($M36="주의","주의",IF($J36>0,"진행","계획"))))) | S36: =IF(OR($G36>'설정'!$D$8,$H36<'설정'!$C$8),"",IF($L36="완료","완료",IF($M36="지연","지연",IF($M36="주의","주의",IF($J36>0,"진행","계획"))))) | T36: =IF(OR($G36>'설정'!$D$9,$H36<'설정'!$C$9),"",IF($L36="완료","완료",IF($M36="지연","지연",IF($M36="주의","주의",IF($J36>0,"진행","계획"))))) -> 완료 | U36: =IF(OR($G36>'설정'!$D$10,$H36<'설정'!$C$10),"",IF($L36="완료","완료",IF($M36="지연","지연",IF($M36="주의","주의",IF($J36>0,"진행","계획"))))) -> 완료 | V36: =IF(OR($G36>'설정'!$D$11,$H36<'설정'!$C$11),"",IF($L36="완료","완료",IF($M36="지연","지연",IF($M36="주의","주의",IF($J36>0,"진행","계획"))))) | W36: =IF(OR($G36>'설정'!$D$12,$H36<'설정'!$C$12),"",IF($L36="완료","완료",IF($M36="지연","지연",IF($M36="주의","주의",IF($J36>0,"진행","계획")))))
A37: WBS-036 | C37: 관리자·추천 콘텐츠 | D37: 송주창 | E37: 관리자 추천 콘텐츠 관리 메뉴와 과목별 목록·필터, 등록·수정·삭제·활성/비활성·노출 순서 관리 구현 | F37: 관리자가 과목별 추천 콘텐츠를 관리하고 활성 콘텐츠만 사용자 커뮤니티 추천 콘텐츠 화면에 노출됨 | G37: 46214 | H37: 46221 | I37: 1 | J37: 1 | K37: 1 | L37: =IF(LEN($K37&"")=0,"",IF($K37>=1,"완료",IF($K37>0,"진행","준비"))) -> 완료 | M37: 정상 | N37: 관리자 | O37: =IF(OR($G37>'설정'!$D$4,$H37<'설정'!$C$4),"",IF($L37="완료","완료",IF($M37="지연","지연",IF($M37="주의","주의",IF($J37>0,"진행","계획"))))) | P37: =IF(OR($G37>'설정'!$D$5,$H37<'설정'!$C$5),"",IF($L37="완료","완료",IF($M37="지연","지연",IF($M37="주의","주의",IF($J37>0,"진행","계획"))))) | Q37: =IF(OR($G37>'설정'!$D$6,$H37<'설정'!$C$6),"",IF($L37="완료","완료",IF($M37="지연","지연",IF($M37="주의","주의",IF($J37>0,"진행","계획"))))) | R37: =IF(OR($G37>'설정'!$D$7,$H37<'설정'!$C$7),"",IF($L37="완료","완료",IF($M37="지연","지연",IF($M37="주의","주의",IF($J37>0,"진행","계획"))))) | S37: =IF(OR($G37>'설정'!$D$8,$H37<'설정'!$C$8),"",IF($L37="완료","완료",IF($M37="지연","지연",IF($M37="주의","주의",IF($J37>0,"진행","계획"))))) | T37: =IF(OR($G37>'설정'!$D$9,$H37<'설정'!$C$9),"",IF($L37="완료","완료",IF($M37="지연","지연",IF($M37="주의","주의",IF($J37>0,"진행","계획"))))) -> 완료 | U37: =IF(OR($G37>'설정'!$D$10,$H37<'설정'!$C$10),"",IF($L37="완료","완료",IF($M37="지연","지연",IF($M37="주의","주의",IF($J37>0,"진행","계획"))))) -> 완료 | V37: =IF(OR($G37>'설정'!$D$11,$H37<'설정'!$C$11),"",IF($L37="완료","완료",IF($M37="지연","지연",IF($M37="주의","주의",IF($J37>0,"진행","계획"))))) | W37: =IF(OR($G37>'설정'!$D$12,$H37<'설정'!$C$12),"",IF($L37="완료","완료",IF($M37="지연","지연",IF($M37="주의","주의",IF($J37>0,"진행","계획")))))
A38: WBS-037 | C38: 결제·Premium·마이페이지 | D38: 박세인 | E38: 카카오페이, PG/결제 취소, Premium 권한·결제 상태 연동 | F38: 결제 요청·성공·실패·취소와 Premium 권한·결제 이력 연동이 확인됨 | G38: 46214 | H38: 46221 | I38: 1 | J38: 1 | K38: =IF(LEN($J38&"")=0,"",$J38) -> 1 | L38: =IF(LEN($K38&"")=0,"",IF($K38>=1,"완료",IF($K38>0,"진행","준비"))) -> 완료 | M38: =IF(OR(LEN($I38&"")=0,LEN($J38&"")=0),"",IF($J38>=1,"정상",IF($J38>=$I38,"정상",IF($I38-$J38>0.1,"지연","주의")))) -> 정상 | N38: 결제 | O38: =IF(OR($G38>'설정'!$D$4,$H38<'설정'!$C$4),"",IF($L38="완료","완료",IF($M38="지연","지연",IF($M38="주의","주의",IF($J38>0,"진행","계획"))))) | P38: =IF(OR($G38>'설정'!$D$5,$H38<'설정'!$C$5),"",IF($L38="완료","완료",IF($M38="지연","지연",IF($M38="주의","주의",IF($J38>0,"진행","계획"))))) | Q38: =IF(OR($G38>'설정'!$D$6,$H38<'설정'!$C$6),"",IF($L38="완료","완료",IF($M38="지연","지연",IF($M38="주의","주의",IF($J38>0,"진행","계획"))))) | R38: =IF(OR($G38>'설정'!$D$7,$H38<'설정'!$C$7),"",IF($L38="완료","완료",IF($M38="지연","지연",IF($M38="주의","주의",IF($J38>0,"진행","계획"))))) | S38: =IF(OR($G38>'설정'!$D$8,$H38<'설정'!$C$8),"",IF($L38="완료","완료",IF($M38="지연","지연",IF($M38="주의","주의",IF($J38>0,"진행","계획"))))) | T38: =IF(OR($G38>'설정'!$D$9,$H38<'설정'!$C$9),"",IF($L38="완료","완료",IF($M38="지연","지연",IF($M38="주의","주의",IF($J38>0,"진행","계획"))))) -> 완료 | U38: =IF(OR($G38>'설정'!$D$10,$H38<'설정'!$C$10),"",IF($L38="완료","완료",IF($M38="지연","지연",IF($M38="주의","주의",IF($J38>0,"진행","계획"))))) -> 완료 | V38: =IF(OR($G38>'설정'!$D$11,$H38<'설정'!$C$11),"",IF($L38="완료","완료",IF($M38="지연","지연",IF($M38="주의","주의",IF($J38>0,"진행","계획"))))) | W38: =IF(OR($G38>'설정'!$D$12,$H38<'설정'!$C$12),"",IF($L38="완료","완료",IF($M38="지연","지연",IF($M38="주의","주의",IF($J38>0,"진행","계획")))))
A39: WBS-038 | C39: 인증·세션·튜토리얼 | D39: 이정하 | E39: 비밀번호 찾기·이메일 재설정, 튜토리얼 누비 좌표 이동 애니메이션 | F39: 이메일 기반 비밀번호 재설정과 튜토리얼 누비 이동 연출이 확인됨 | G39: 46214 | H39: 46221 | I39: 1 | J39: 1 | K39: =IF(LEN($J39&"")=0,"",$J39) -> 1 | L39: =IF(LEN($K39&"")=0,"",IF($K39>=1,"완료",IF($K39>0,"진행","준비"))) -> 완료 | M39: =IF(OR(LEN($I39&"")=0,LEN($J39&"")=0),"",IF($J39>=1,"정상",IF($J39>=$I39,"정상",IF($I39-$J39>0.1,"지연","주의")))) -> 정상 | N39: 인증 | O39: =IF(OR($G39>'설정'!$D$4,$H39<'설정'!$C$4),"",IF($L39="완료","완료",IF($M39="지연","지연",IF($M39="주의","주의",IF($J39>0,"진행","계획"))))) | P39: =IF(OR($G39>'설정'!$D$5,$H39<'설정'!$C$5),"",IF($L39="완료","완료",IF($M39="지연","지연",IF($M39="주의","주의",IF($J39>0,"진행","계획"))))) | Q39: =IF(OR($G39>'설정'!$D$6,$H39<'설정'!$C$6),"",IF($L39="완료","완료",IF($M39="지연","지연",IF($M39="주의","주의",IF($J39>0,"진행","계획"))))) | R39: =IF(OR($G39>'설정'!$D$7,$H39<'설정'!$C$7),"",IF($L39="완료","완료",IF($M39="지연","지연",IF($M39="주의","주의",IF($J39>0,"진행","계획"))))) | S39: =IF(OR($G39>'설정'!$D$8,$H39<'설정'!$C$8),"",IF($L39="완료","완료",IF($M39="지연","지연",IF($M39="주의","주의",IF($J39>0,"진행","계획"))))) | T39: =IF(OR($G39>'설정'!$D$9,$H39<'설정'!$C$9),"",IF($L39="완료","완료",IF($M39="지연","지연",IF($M39="주의","주의",IF($J39>0,"진행","계획"))))) -> 완료 | U39: =IF(OR($G39>'설정'!$D$10,$H39<'설정'!$C$10),"",IF($L39="완료","완료",IF($M39="지연","지연",IF($M39="주의","주의",IF($J39>0,"진행","계획"))))) -> 완료 | V39: =IF(OR($G39>'설정'!$D$11,$H39<'설정'!$C$11),"",IF($L39="완료","완료",IF($M39="지연","지연",IF($M39="주의","주의",IF($J39>0,"진행","계획"))))) | W39: =IF(OR($G39>'설정'!$D$12,$H39<'설정'!$C$12),"",IF($L39="완료","완료",IF($M39="지연","지연",IF($M39="주의","주의",IF($J39>0,"진행","계획")))))
